2020-03-26 11:07:01 [scrapy] DEBUG: Crawled (404) <GET http://quotes.toscrape.com/robots.txt> (referer: None)
2020-03-26 11:07:01 [scrapy] DEBUG: Crawled (200) <GET http://quotes.toscrape.com/> (referer: None)
2020-03-26 11:07:32 [scrapy] ERROR: Error processing {'author': 'Albert Einstein',
 'tags': ['change', 'deep-thoughts', 'thinking', 'world'],
 'text': '“The world as we have created it is a process of o...'}
Traceback (most recent call last):
  File "c:\users\w\anaconda3\lib\site-packages\twisted\internet\defer.py", line 654, in _runCallbacks
    current.result = callback(current.result, *args, **kw)
  File "c:\users\w\anaconda3\lib\site-packages\scrapy\utils\defer.py", line 154, in f
    return deferred_from_coro(coro_f(*coro_args, **coro_kwargs))
  File "E:\scrapy\ScrapyTutorial-master\tutorial\pipelines.py", line 36, in process_item
    self.db[name].insert(dict(item))
  File "c:\users\w\anaconda3\lib\site-packages\pymongo\collection.py", line 3182, in insert
    check_keys, manipulate, write_concern)
  File "c:\users\w\anaconda3\lib\site-packages\pymongo\collection.py", line 612, in _insert
    bypass_doc_val, session)
  File "c:\users\w\anaconda3\lib\site-packages\pymongo\collection.py", line 600, in _insert_one
    acknowledged, _insert_command, session)
  File "c:\users\w\anaconda3\lib\site-packages\pymongo\mongo_client.py", line 1491, in _retryable_write
    with self._tmp_session(session) as s:
  File "c:\users\w\anaconda3\lib\contextlib.py", line 59, in __enter__
    return next(self.gen)
  File "c:\users\w\anaconda3\lib\site-packages\pymongo\mongo_client.py", line 1820, in _tmp_session
    s = self._ensure_session(session)
  File "c:\users\w\anaconda3\lib\site-packages\pymongo\mongo_client.py", line 1807, in _ensure_session
    return self.__start_session(True, causal_consistency=False)
  File "c:\users\w\anaconda3\lib\site-packages\pymongo\mongo_client.py", line 1760, in __start_session
    server_session = self._get_server_session()
  File "c:\users\w\anaconda3\lib\site-packages\pymongo\mongo_client.py", line 1793, in _get_server_session
    return self._topology.get_server_session()
  File "c:\users\w\anaconda3\lib\site-packages\pymongo\topology.py", line 477, in get_server_session
    None)
  File "c:\users\w\anaconda3\lib\site-packages\pymongo\topology.py", line 205, in _select_servers_loop
    self._error_message(selector))
pymongo.errors.ServerSelectionTimeoutError: localhost:27017: [WinError 10061] 由于目标计算机积极拒绝，无法连接。
2020-03-26 11:08:02 [scrapy] ERROR: Error processing {'author': 'J.K. Rowling',
 'tags': ['abilities', 'choices'],
 'text': '“It is our choices, Harry, that show what we truly...'}
Traceback (most recent call last):
  File "c:\users\w\anaconda3\lib\site-packages\twisted\internet\defer.py", line 654, in _runCallbacks
    current.result = callback(current.result, *args, **kw)
  File "c:\users\w\anaconda3\lib\site-packages\scrapy\utils\defer.py", line 154, in f
    return deferred_from_coro(coro_f(*coro_args, **coro_kwargs))
  File "E:\scrapy\ScrapyTutorial-master\tutorial\pipelines.py", line 36, in process_item
    self.db[name].insert(dict(item))
  File "c:\users\w\anaconda3\lib\site-packages\pymongo\collection.py", line 3182, in insert
    check_keys, manipulate, write_concern)
  File "c:\users\w\anaconda3\lib\site-packages\pymongo\collection.py", line 612, in _insert
    bypass_doc_val, session)
  File "c:\users\w\anaconda3\lib\site-packages\pymongo\collection.py", line 600, in _insert_one
    acknowledged, _insert_command, session)
  File "c:\users\w\anaconda3\lib\site-packages\pymongo\mongo_client.py", line 1491, in _retryable_write
    with self._tmp_session(session) as s:
  File "c:\users\w\anaconda3\lib\contextlib.py", line 59, in __enter__
    return next(self.gen)
  File "c:\users\w\anaconda3\lib\site-packages\pymongo\mongo_client.py", line 1820, in _tmp_session
    s = self._ensure_session(session)
  File "c:\users\w\anaconda3\lib\site-packages\pymongo\mongo_client.py", line 1807, in _ensure_session
    return self.__start_session(True, causal_consistency=False)
  File "c:\users\w\anaconda3\lib\site-packages\pymongo\mongo_client.py", line 1760, in __start_session
    server_session = self._get_server_session()
  File "c:\users\w\anaconda3\lib\site-packages\pymongo\mongo_client.py", line 1793, in _get_server_session
    return self._topology.get_server_session()
  File "c:\users\w\anaconda3\lib\site-packages\pymongo\topology.py", line 477, in get_server_session
    None)
  File "c:\users\w\anaconda3\lib\site-packages\pymongo\topology.py", line 205, in _select_servers_loop
    self._error_message(selector))
pymongo.errors.ServerSelectionTimeoutError: localhost:27017: [WinError 10061] 由于目标计算机积极拒绝，无法连接。
2020-03-26 11:08:32 [scrapy] ERROR: Error processing {'author': 'Albert Einstein',
 'tags': ['inspirational', 'life', 'live', 'miracle', 'miracles'],
 'text': '“There are only two ways to live your life. One is...'}
Traceback (most recent call last):
  File "c:\users\w\anaconda3\lib\site-packages\twisted\internet\defer.py", line 654, in _runCallbacks
    current.result = callback(current.result, *args, **kw)
  File "c:\users\w\anaconda3\lib\site-packages\scrapy\utils\defer.py", line 154, in f
    return deferred_from_coro(coro_f(*coro_args, **coro_kwargs))
  File "E:\scrapy\ScrapyTutorial-master\tutorial\pipelines.py", line 36, in process_item
    self.db[name].insert(dict(item))
  File "c:\users\w\anaconda3\lib\site-packages\pymongo\collection.py", line 3182, in insert
    check_keys, manipulate, write_concern)
  File "c:\users\w\anaconda3\lib\site-packages\pymongo\collection.py", line 612, in _insert
    bypass_doc_val, session)
  File "c:\users\w\anaconda3\lib\site-packages\pymongo\collection.py", line 600, in _insert_one
    acknowledged, _insert_command, session)
  File "c:\users\w\anaconda3\lib\site-packages\pymongo\mongo_client.py", line 1491, in _retryable_write
    with self._tmp_session(session) as s:
  File "c:\users\w\anaconda3\lib\contextlib.py", line 59, in __enter__
    return next(self.gen)
  File "c:\users\w\anaconda3\lib\site-packages\pymongo\mongo_client.py", line 1820, in _tmp_session
    s = self._ensure_session(session)
  File "c:\users\w\anaconda3\lib\site-packages\pymongo\mongo_client.py", line 1807, in _ensure_session
    return self.__start_session(True, causal_consistency=False)
  File "c:\users\w\anaconda3\lib\site-packages\pymongo\mongo_client.py", line 1760, in __start_session
    server_session = self._get_server_session()
  File "c:\users\w\anaconda3\lib\site-packages\pymongo\mongo_client.py", line 1793, in _get_server_session
    return self._topology.get_server_session()
  File "c:\users\w\anaconda3\lib\site-packages\pymongo\topology.py", line 477, in get_server_session
    None)
  File "c:\users\w\anaconda3\lib\site-packages\pymongo\topology.py", line 205, in _select_servers_loop
    self._error_message(selector))
pymongo.errors.ServerSelectionTimeoutError: localhost:27017: [WinError 10061] 由于目标计算机积极拒绝，无法连接。
2020-03-26 11:09:02 [scrapy] ERROR: Error processing {'author': 'Jane Austen',
 'tags': ['aliteracy', 'books', 'classic', 'humor'],
 'text': '“The person, be it gentleman or lady, who has not...'}
Traceback (most recent call last):
  File "c:\users\w\anaconda3\lib\site-packages\twisted\internet\defer.py", line 654, in _runCallbacks
    current.result = callback(current.result, *args, **kw)
  File "c:\users\w\anaconda3\lib\site-packages\scrapy\utils\defer.py", line 154, in f
    return deferred_from_coro(coro_f(*coro_args, **coro_kwargs))
  File "E:\scrapy\ScrapyTutorial-master\tutorial\pipelines.py", line 36, in process_item
    self.db[name].insert(dict(item))
  File "c:\users\w\anaconda3\lib\site-packages\pymongo\collection.py", line 3182, in insert
    check_keys, manipulate, write_concern)
  File "c:\users\w\anaconda3\lib\site-packages\pymongo\collection.py", line 612, in _insert
    bypass_doc_val, session)
  File "c:\users\w\anaconda3\lib\site-packages\pymongo\collection.py", line 600, in _insert_one
    acknowledged, _insert_command, session)
  File "c:\users\w\anaconda3\lib\site-packages\pymongo\mongo_client.py", line 1491, in _retryable_write
    with self._tmp_session(session) as s:
  File "c:\users\w\anaconda3\lib\contextlib.py", line 59, in __enter__
    return next(self.gen)
  File "c:\users\w\anaconda3\lib\site-packages\pymongo\mongo_client.py", line 1820, in _tmp_session
    s = self._ensure_session(session)
  File "c:\users\w\anaconda3\lib\site-packages\pymongo\mongo_client.py", line 1807, in _ensure_session
    return self.__start_session(True, causal_consistency=False)
  File "c:\users\w\anaconda3\lib\site-packages\pymongo\mongo_client.py", line 1760, in __start_session
    server_session = self._get_server_session()
  File "c:\users\w\anaconda3\lib\site-packages\pymongo\mongo_client.py", line 1793, in _get_server_session
    return self._topology.get_server_session()
  File "c:\users\w\anaconda3\lib\site-packages\pymongo\topology.py", line 477, in get_server_session
    None)
  File "c:\users\w\anaconda3\lib\site-packages\pymongo\topology.py", line 205, in _select_servers_loop
    self._error_message(selector))
pymongo.errors.ServerSelectionTimeoutError: localhost:27017: [WinError 10061] 由于目标计算机积极拒绝，无法连接。
2020-03-26 11:09:33 [scrapy] ERROR: Error processing {'author': 'Marilyn Monroe',
 'tags': ['be-yourself', 'inspirational'],
 'text': "“Imperfection is beauty, madness is genius and it'..."}
Traceback (most recent call last):
  File "c:\users\w\anaconda3\lib\site-packages\twisted\internet\defer.py", line 654, in _runCallbacks
    current.result = callback(current.result, *args, **kw)
  File "c:\users\w\anaconda3\lib\site-packages\scrapy\utils\defer.py", line 154, in f
    return deferred_from_coro(coro_f(*coro_args, **coro_kwargs))
  File "E:\scrapy\ScrapyTutorial-master\tutorial\pipelines.py", line 36, in process_item
    self.db[name].insert(dict(item))
  File "c:\users\w\anaconda3\lib\site-packages\pymongo\collection.py", line 3182, in insert
    check_keys, manipulate, write_concern)
  File "c:\users\w\anaconda3\lib\site-packages\pymongo\collection.py", line 612, in _insert
    bypass_doc_val, session)
  File "c:\users\w\anaconda3\lib\site-packages\pymongo\collection.py", line 600, in _insert_one
    acknowledged, _insert_command, session)
  File "c:\users\w\anaconda3\lib\site-packages\pymongo\mongo_client.py", line 1491, in _retryable_write
    with self._tmp_session(session) as s:
  File "c:\users\w\anaconda3\lib\contextlib.py", line 59, in __enter__
    return next(self.gen)
  File "c:\users\w\anaconda3\lib\site-packages\pymongo\mongo_client.py", line 1820, in _tmp_session
    s = self._ensure_session(session)
  File "c:\users\w\anaconda3\lib\site-packages\pymongo\mongo_client.py", line 1807, in _ensure_session
    return self.__start_session(True, causal_consistency=False)
  File "c:\users\w\anaconda3\lib\site-packages\pymongo\mongo_client.py", line 1760, in __start_session
    server_session = self._get_server_session()
  File "c:\users\w\anaconda3\lib\site-packages\pymongo\mongo_client.py", line 1793, in _get_server_session
    return self._topology.get_server_session()
  File "c:\users\w\anaconda3\lib\site-packages\pymongo\topology.py", line 477, in get_server_session
    None)
  File "c:\users\w\anaconda3\lib\site-packages\pymongo\topology.py", line 205, in _select_servers_loop
    self._error_message(selector))
pymongo.errors.ServerSelectionTimeoutError: localhost:27017: [WinError 10061] 由于目标计算机积极拒绝，无法连接。
2020-03-26 11:10:03 [scrapy] ERROR: Error processing {'author': 'Albert Einstein',
 'tags': ['adulthood', 'success', 'value'],
 'text': '“Try not to become a man of success. Rather become...'}
Traceback (most recent call last):
  File "c:\users\w\anaconda3\lib\site-packages\twisted\internet\defer.py", line 654, in _runCallbacks
    current.result = callback(current.result, *args, **kw)
  File "c:\users\w\anaconda3\lib\site-packages\scrapy\utils\defer.py", line 154, in f
    return deferred_from_coro(coro_f(*coro_args, **coro_kwargs))
  File "E:\scrapy\ScrapyTutorial-master\tutorial\pipelines.py", line 36, in process_item
    self.db[name].insert(dict(item))
  File "c:\users\w\anaconda3\lib\site-packages\pymongo\collection.py", line 3182, in insert
    check_keys, manipulate, write_concern)
  File "c:\users\w\anaconda3\lib\site-packages\pymongo\collection.py", line 612, in _insert
    bypass_doc_val, session)
  File "c:\users\w\anaconda3\lib\site-packages\pymongo\collection.py", line 600, in _insert_one
    acknowledged, _insert_command, session)
  File "c:\users\w\anaconda3\lib\site-packages\pymongo\mongo_client.py", line 1491, in _retryable_write
    with self._tmp_session(session) as s:
  File "c:\users\w\anaconda3\lib\contextlib.py", line 59, in __enter__
    return next(self.gen)
  File "c:\users\w\anaconda3\lib\site-packages\pymongo\mongo_client.py", line 1820, in _tmp_session
    s = self._ensure_session(session)
  File "c:\users\w\anaconda3\lib\site-packages\pymongo\mongo_client.py", line 1807, in _ensure_session
    return self.__start_session(True, causal_consistency=False)
  File "c:\users\w\anaconda3\lib\site-packages\pymongo\mongo_client.py", line 1760, in __start_session
    server_session = self._get_server_session()
  File "c:\users\w\anaconda3\lib\site-packages\pymongo\mongo_client.py", line 1793, in _get_server_session
    return self._topology.get_server_session()
  File "c:\users\w\anaconda3\lib\site-packages\pymongo\topology.py", line 477, in get_server_session
    None)
  File "c:\users\w\anaconda3\lib\site-packages\pymongo\topology.py", line 205, in _select_servers_loop
    self._error_message(selector))
pymongo.errors.ServerSelectionTimeoutError: localhost:27017: [WinError 10061] 由于目标计算机积极拒绝，无法连接。
2020-03-26 11:10:33 [scrapy] ERROR: Error processing {'author': 'André Gide',
 'tags': ['life', 'love'],
 'text': '“It is better to be hated for what you are than to...'}
Traceback (most recent call last):
  File "c:\users\w\anaconda3\lib\site-packages\twisted\internet\defer.py", line 654, in _runCallbacks
    current.result = callback(current.result, *args, **kw)
  File "c:\users\w\anaconda3\lib\site-packages\scrapy\utils\defer.py", line 154, in f
    return deferred_from_coro(coro_f(*coro_args, **coro_kwargs))
  File "E:\scrapy\ScrapyTutorial-master\tutorial\pipelines.py", line 36, in process_item
    self.db[name].insert(dict(item))
  File "c:\users\w\anaconda3\lib\site-packages\pymongo\collection.py", line 3182, in insert
    check_keys, manipulate, write_concern)
  File "c:\users\w\anaconda3\lib\site-packages\pymongo\collection.py", line 612, in _insert
    bypass_doc_val, session)
  File "c:\users\w\anaconda3\lib\site-packages\pymongo\collection.py", line 600, in _insert_one
    acknowledged, _insert_command, session)
  File "c:\users\w\anaconda3\lib\site-packages\pymongo\mongo_client.py", line 1491, in _retryable_write
    with self._tmp_session(session) as s:
  File "c:\users\w\anaconda3\lib\contextlib.py", line 59, in __enter__
    return next(self.gen)
  File "c:\users\w\anaconda3\lib\site-packages\pymongo\mongo_client.py", line 1820, in _tmp_session
    s = self._ensure_session(session)
  File "c:\users\w\anaconda3\lib\site-packages\pymongo\mongo_client.py", line 1807, in _ensure_session
    return self.__start_session(True, causal_consistency=False)
  File "c:\users\w\anaconda3\lib\site-packages\pymongo\mongo_client.py", line 1760, in __start_session
    server_session = self._get_server_session()
  File "c:\users\w\anaconda3\lib\site-packages\pymongo\mongo_client.py", line 1793, in _get_server_session
    return self._topology.get_server_session()
  File "c:\users\w\anaconda3\lib\site-packages\pymongo\topology.py", line 477, in get_server_session
    None)
  File "c:\users\w\anaconda3\lib\site-packages\pymongo\topology.py", line 205, in _select_servers_loop
    self._error_message(selector))
pymongo.errors.ServerSelectionTimeoutError: localhost:27017: [WinError 10061] 由于目标计算机积极拒绝，无法连接。
2020-03-26 11:11:03 [scrapy] ERROR: Error processing {'author': 'Thomas A. Edison',
 'tags': ['edison', 'failure', 'inspirational', 'paraphrased'],
 'text': "“I have not failed. I've just found 10,000 ways th..."}
Traceback (most recent call last):
  File "c:\users\w\anaconda3\lib\site-packages\twisted\internet\defer.py", line 654, in _runCallbacks
    current.result = callback(current.result, *args, **kw)
  File "c:\users\w\anaconda3\lib\site-packages\scrapy\utils\defer.py", line 154, in f
    return deferred_from_coro(coro_f(*coro_args, **coro_kwargs))
  File "E:\scrapy\ScrapyTutorial-master\tutorial\pipelines.py", line 36, in process_item
    self.db[name].insert(dict(item))
  File "c:\users\w\anaconda3\lib\site-packages\pymongo\collection.py", line 3182, in insert
    check_keys, manipulate, write_concern)
  File "c:\users\w\anaconda3\lib\site-packages\pymongo\collection.py", line 612, in _insert
    bypass_doc_val, session)
  File "c:\users\w\anaconda3\lib\site-packages\pymongo\collection.py", line 600, in _insert_one
    acknowledged, _insert_command, session)
  File "c:\users\w\anaconda3\lib\site-packages\pymongo\mongo_client.py", line 1491, in _retryable_write
    with self._tmp_session(session) as s:
  File "c:\users\w\anaconda3\lib\contextlib.py", line 59, in __enter__
    return next(self.gen)
  File "c:\users\w\anaconda3\lib\site-packages\pymongo\mongo_client.py", line 1820, in _tmp_session
    s = self._ensure_session(session)
  File "c:\users\w\anaconda3\lib\site-packages\pymongo\mongo_client.py", line 1807, in _ensure_session
    return self.__start_session(True, causal_consistency=False)
  File "c:\users\w\anaconda3\lib\site-packages\pymongo\mongo_client.py", line 1760, in __start_session
    server_session = self._get_server_session()
  File "c:\users\w\anaconda3\lib\site-packages\pymongo\mongo_client.py", line 1793, in _get_server_session
    return self._topology.get_server_session()
  File "c:\users\w\anaconda3\lib\site-packages\pymongo\topology.py", line 477, in get_server_session
    None)
  File "c:\users\w\anaconda3\lib\site-packages\pymongo\topology.py", line 205, in _select_servers_loop
    self._error_message(selector))
pymongo.errors.ServerSelectionTimeoutError: localhost:27017: [WinError 10061] 由于目标计算机积极拒绝，无法连接。
2020-03-26 11:11:33 [scrapy] ERROR: Error processing {'author': 'Eleanor Roosevelt',
 'tags': ['misattributed-eleanor-roosevelt'],
 'text': '“A woman is like a tea bag; you never know how str...'}
Traceback (most recent call last):
  File "c:\users\w\anaconda3\lib\site-packages\twisted\internet\defer.py", line 654, in _runCallbacks
    current.result = callback(current.result, *args, **kw)
  File "c:\users\w\anaconda3\lib\site-packages\scrapy\utils\defer.py", line 154, in f
    return deferred_from_coro(coro_f(*coro_args, **coro_kwargs))
  File "E:\scrapy\ScrapyTutorial-master\tutorial\pipelines.py", line 36, in process_item
    self.db[name].insert(dict(item))
  File "c:\users\w\anaconda3\lib\site-packages\pymongo\collection.py", line 3182, in insert
    check_keys, manipulate, write_concern)
  File "c:\users\w\anaconda3\lib\site-packages\pymongo\collection.py", line 612, in _insert
    bypass_doc_val, session)
  File "c:\users\w\anaconda3\lib\site-packages\pymongo\collection.py", line 600, in _insert_one
    acknowledged, _insert_command, session)
  File "c:\users\w\anaconda3\lib\site-packages\pymongo\mongo_client.py", line 1491, in _retryable_write
    with self._tmp_session(session) as s:
  File "c:\users\w\anaconda3\lib\contextlib.py", line 59, in __enter__
    return next(self.gen)
  File "c:\users\w\anaconda3\lib\site-packages\pymongo\mongo_client.py", line 1820, in _tmp_session
    s = self._ensure_session(session)
  File "c:\users\w\anaconda3\lib\site-packages\pymongo\mongo_client.py", line 1807, in _ensure_session
    return self.__start_session(True, causal_consistency=False)
  File "c:\users\w\anaconda3\lib\site-packages\pymongo\mongo_client.py", line 1760, in __start_session
    server_session = self._get_server_session()
  File "c:\users\w\anaconda3\lib\site-packages\pymongo\mongo_client.py", line 1793, in _get_server_session
    return self._topology.get_server_session()
  File "c:\users\w\anaconda3\lib\site-packages\pymongo\topology.py", line 477, in get_server_session
    None)
  File "c:\users\w\anaconda3\lib\site-packages\pymongo\topology.py", line 205, in _select_servers_loop
    self._error_message(selector))
pymongo.errors.ServerSelectionTimeoutError: localhost:27017: [WinError 10061] 由于目标计算机积极拒绝，无法连接。
2020-03-26 11:12:03 [scrapy] ERROR: Error processing {'author': 'Steve Martin',
 'tags': ['humor', 'obvious', 'simile'],
 'text': '“A day without sunshine is like, you know, night.”'}
Traceback (most recent call last):
  File "c:\users\w\anaconda3\lib\site-packages\twisted\internet\defer.py", line 654, in _runCallbacks
    current.result = callback(current.result, *args, **kw)
  File "c:\users\w\anaconda3\lib\site-packages\scrapy\utils\defer.py", line 154, in f
    return deferred_from_coro(coro_f(*coro_args, **coro_kwargs))
  File "E:\scrapy\ScrapyTutorial-master\tutorial\pipelines.py", line 36, in process_item
    self.db[name].insert(dict(item))
  File "c:\users\w\anaconda3\lib\site-packages\pymongo\collection.py", line 3182, in insert
    check_keys, manipulate, write_concern)
  File "c:\users\w\anaconda3\lib\site-packages\pymongo\collection.py", line 612, in _insert
    bypass_doc_val, session)
  File "c:\users\w\anaconda3\lib\site-packages\pymongo\collection.py", line 600, in _insert_one
    acknowledged, _insert_command, session)
  File "c:\users\w\anaconda3\lib\site-packages\pymongo\mongo_client.py", line 1491, in _retryable_write
    with self._tmp_session(session) as s:
  File "c:\users\w\anaconda3\lib\contextlib.py", line 59, in __enter__
    return next(self.gen)
  File "c:\users\w\anaconda3\lib\site-packages\pymongo\mongo_client.py", line 1820, in _tmp_session
    s = self._ensure_session(session)
  File "c:\users\w\anaconda3\lib\site-packages\pymongo\mongo_client.py", line 1807, in _ensure_session
    return self.__start_session(True, causal_consistency=False)
  File "c:\users\w\anaconda3\lib\site-packages\pymongo\mongo_client.py", line 1760, in __start_session
    server_session = self._get_server_session()
  File "c:\users\w\anaconda3\lib\site-packages\pymongo\mongo_client.py", line 1793, in _get_server_session
    return self._topology.get_server_session()
  File "c:\users\w\anaconda3\lib\site-packages\pymongo\topology.py", line 477, in get_server_session
    None)
  File "c:\users\w\anaconda3\lib\site-packages\pymongo\topology.py", line 205, in _select_servers_loop
    self._error_message(selector))
pymongo.errors.ServerSelectionTimeoutError: localhost:27017: [WinError 10061] 由于目标计算机积极拒绝，无法连接。
2020-03-26 11:12:04 [scrapy] DEBUG: Crawled (200) <GET http://quotes.toscrape.com/page/2/> (referer: http://quotes.toscrape.com/)
2020-03-26 11:12:35 [scrapy] ERROR: Error processing {'author': 'Marilyn Monroe',
 'tags': ['friends', 'heartbreak', 'inspirational', 'life', 'love', 'sisters'],
 'text': '“This life is what you make it. No matter what, yo...'}
Traceback (most recent call last):
  File "c:\users\w\anaconda3\lib\site-packages\twisted\internet\defer.py", line 654, in _runCallbacks
    current.result = callback(current.result, *args, **kw)
  File "c:\users\w\anaconda3\lib\site-packages\scrapy\utils\defer.py", line 154, in f
    return deferred_from_coro(coro_f(*coro_args, **coro_kwargs))
  File "E:\scrapy\ScrapyTutorial-master\tutorial\pipelines.py", line 36, in process_item
    self.db[name].insert(dict(item))
  File "c:\users\w\anaconda3\lib\site-packages\pymongo\collection.py", line 3182, in insert
    check_keys, manipulate, write_concern)
  File "c:\users\w\anaconda3\lib\site-packages\pymongo\collection.py", line 612, in _insert
    bypass_doc_val, session)
  File "c:\users\w\anaconda3\lib\site-packages\pymongo\collection.py", line 600, in _insert_one
    acknowledged, _insert_command, session)
  File "c:\users\w\anaconda3\lib\site-packages\pymongo\mongo_client.py", line 1491, in _retryable_write
    with self._tmp_session(session) as s:
  File "c:\users\w\anaconda3\lib\contextlib.py", line 59, in __enter__
    return next(self.gen)
  File "c:\users\w\anaconda3\lib\site-packages\pymongo\mongo_client.py", line 1820, in _tmp_session
    s = self._ensure_session(session)
  File "c:\users\w\anaconda3\lib\site-packages\pymongo\mongo_client.py", line 1807, in _ensure_session
    return self.__start_session(True, causal_consistency=False)
  File "c:\users\w\anaconda3\lib\site-packages\pymongo\mongo_client.py", line 1760, in __start_session
    server_session = self._get_server_session()
  File "c:\users\w\anaconda3\lib\site-packages\pymongo\mongo_client.py", line 1793, in _get_server_session
    return self._topology.get_server_session()
  File "c:\users\w\anaconda3\lib\site-packages\pymongo\topology.py", line 477, in get_server_session
    None)
  File "c:\users\w\anaconda3\lib\site-packages\pymongo\topology.py", line 205, in _select_servers_loop
    self._error_message(selector))
pymongo.errors.ServerSelectionTimeoutError: localhost:27017: [WinError 10061] 由于目标计算机积极拒绝，无法连接。
2020-03-26 11:13:05 [scrapy] ERROR: Error processing {'author': 'J.K. Rowling',
 'tags': ['courage', 'friends'],
 'text': '“It takes a great deal of bravery to stand up to o...'}
Traceback (most recent call last):
  File "c:\users\w\anaconda3\lib\site-packages\twisted\internet\defer.py", line 654, in _runCallbacks
    current.result = callback(current.result, *args, **kw)
  File "c:\users\w\anaconda3\lib\site-packages\scrapy\utils\defer.py", line 154, in f
    return deferred_from_coro(coro_f(*coro_args, **coro_kwargs))
  File "E:\scrapy\ScrapyTutorial-master\tutorial\pipelines.py", line 36, in process_item
    self.db[name].insert(dict(item))
  File "c:\users\w\anaconda3\lib\site-packages\pymongo\collection.py", line 3182, in insert
    check_keys, manipulate, write_concern)
  File "c:\users\w\anaconda3\lib\site-packages\pymongo\collection.py", line 612, in _insert
    bypass_doc_val, session)
  File "c:\users\w\anaconda3\lib\site-packages\pymongo\collection.py", line 600, in _insert_one
    acknowledged, _insert_command, session)
  File "c:\users\w\anaconda3\lib\site-packages\pymongo\mongo_client.py", line 1491, in _retryable_write
    with self._tmp_session(session) as s:
  File "c:\users\w\anaconda3\lib\contextlib.py", line 59, in __enter__
    return next(self.gen)
  File "c:\users\w\anaconda3\lib\site-packages\pymongo\mongo_client.py", line 1820, in _tmp_session
    s = self._ensure_session(session)
  File "c:\users\w\anaconda3\lib\site-packages\pymongo\mongo_client.py", line 1807, in _ensure_session
    return self.__start_session(True, causal_consistency=False)
  File "c:\users\w\anaconda3\lib\site-packages\pymongo\mongo_client.py", line 1760, in __start_session
    server_session = self._get_server_session()
  File "c:\users\w\anaconda3\lib\site-packages\pymongo\mongo_client.py", line 1793, in _get_server_session
    return self._topology.get_server_session()
  File "c:\users\w\anaconda3\lib\site-packages\pymongo\topology.py", line 477, in get_server_session
    None)
  File "c:\users\w\anaconda3\lib\site-packages\pymongo\topology.py", line 205, in _select_servers_loop
    self._error_message(selector))
pymongo.errors.ServerSelectionTimeoutError: localhost:27017: [WinError 10061] 由于目标计算机积极拒绝，无法连接。
2020-03-26 11:13:35 [scrapy] ERROR: Error processing {'author': 'Albert Einstein',
 'tags': ['simplicity', 'understand'],
 'text': "“If you can't explain it to a six year old, you do..."}
Traceback (most recent call last):
  File "c:\users\w\anaconda3\lib\site-packages\twisted\internet\defer.py", line 654, in _runCallbacks
    current.result = callback(current.result, *args, **kw)
  File "c:\users\w\anaconda3\lib\site-packages\scrapy\utils\defer.py", line 154, in f
    return deferred_from_coro(coro_f(*coro_args, **coro_kwargs))
  File "E:\scrapy\ScrapyTutorial-master\tutorial\pipelines.py", line 36, in process_item
    self.db[name].insert(dict(item))
  File "c:\users\w\anaconda3\lib\site-packages\pymongo\collection.py", line 3182, in insert
    check_keys, manipulate, write_concern)
  File "c:\users\w\anaconda3\lib\site-packages\pymongo\collection.py", line 612, in _insert
    bypass_doc_val, session)
  File "c:\users\w\anaconda3\lib\site-packages\pymongo\collection.py", line 600, in _insert_one
    acknowledged, _insert_command, session)
  File "c:\users\w\anaconda3\lib\site-packages\pymongo\mongo_client.py", line 1491, in _retryable_write
    with self._tmp_session(session) as s:
  File "c:\users\w\anaconda3\lib\contextlib.py", line 59, in __enter__
    return next(self.gen)
  File "c:\users\w\anaconda3\lib\site-packages\pymongo\mongo_client.py", line 1820, in _tmp_session
    s = self._ensure_session(session)
  File "c:\users\w\anaconda3\lib\site-packages\pymongo\mongo_client.py", line 1807, in _ensure_session
    return self.__start_session(True, causal_consistency=False)
  File "c:\users\w\anaconda3\lib\site-packages\pymongo\mongo_client.py", line 1760, in __start_session
    server_session = self._get_server_session()
  File "c:\users\w\anaconda3\lib\site-packages\pymongo\mongo_client.py", line 1793, in _get_server_session
    return self._topology.get_server_session()
  File "c:\users\w\anaconda3\lib\site-packages\pymongo\topology.py", line 477, in get_server_session
    None)
  File "c:\users\w\anaconda3\lib\site-packages\pymongo\topology.py", line 205, in _select_servers_loop
    self._error_message(selector))
pymongo.errors.ServerSelectionTimeoutError: localhost:27017: [WinError 10061] 由于目标计算机积极拒绝，无法连接。
2020-03-26 11:14:05 [scrapy] ERROR: Error processing {'author': 'Bob Marley',
 'tags': ['love'],
 'text': '“You may not be her first, her last, or her only....'}
Traceback (most recent call last):
  File "c:\users\w\anaconda3\lib\site-packages\twisted\internet\defer.py", line 654, in _runCallbacks
    current.result = callback(current.result, *args, **kw)
  File "c:\users\w\anaconda3\lib\site-packages\scrapy\utils\defer.py", line 154, in f
    return deferred_from_coro(coro_f(*coro_args, **coro_kwargs))
  File "E:\scrapy\ScrapyTutorial-master\tutorial\pipelines.py", line 36, in process_item
    self.db[name].insert(dict(item))
  File "c:\users\w\anaconda3\lib\site-packages\pymongo\collection.py", line 3182, in insert
    check_keys, manipulate, write_concern)
  File "c:\users\w\anaconda3\lib\site-packages\pymongo\collection.py", line 612, in _insert
    bypass_doc_val, session)
  File "c:\users\w\anaconda3\lib\site-packages\pymongo\collection.py", line 600, in _insert_one
    acknowledged, _insert_command, session)
  File "c:\users\w\anaconda3\lib\site-packages\pymongo\mongo_client.py", line 1491, in _retryable_write
    with self._tmp_session(session) as s:
  File "c:\users\w\anaconda3\lib\contextlib.py", line 59, in __enter__
    return next(self.gen)
  File "c:\users\w\anaconda3\lib\site-packages\pymongo\mongo_client.py", line 1820, in _tmp_session
    s = self._ensure_session(session)
  File "c:\users\w\anaconda3\lib\site-packages\pymongo\mongo_client.py", line 1807, in _ensure_session
    return self.__start_session(True, causal_consistency=False)
  File "c:\users\w\anaconda3\lib\site-packages\pymongo\mongo_client.py", line 1760, in __start_session
    server_session = self._get_server_session()
  File "c:\users\w\anaconda3\lib\site-packages\pymongo\mongo_client.py", line 1793, in _get_server_session
    return self._topology.get_server_session()
  File "c:\users\w\anaconda3\lib\site-packages\pymongo\topology.py", line 477, in get_server_session
    None)
  File "c:\users\w\anaconda3\lib\site-packages\pymongo\topology.py", line 205, in _select_servers_loop
    self._error_message(selector))
pymongo.errors.ServerSelectionTimeoutError: localhost:27017: [WinError 10061] 由于目标计算机积极拒绝，无法连接。
2020-03-26 11:14:35 [scrapy] ERROR: Error processing {'author': 'Dr. Seuss',
 'tags': ['fantasy'],
 'text': '“I like nonsense, it wakes up the brain cells. Fan...'}
Traceback (most recent call last):
  File "c:\users\w\anaconda3\lib\site-packages\twisted\internet\defer.py", line 654, in _runCallbacks
    current.result = callback(current.result, *args, **kw)
  File "c:\users\w\anaconda3\lib\site-packages\scrapy\utils\defer.py", line 154, in f
    return deferred_from_coro(coro_f(*coro_args, **coro_kwargs))
  File "E:\scrapy\ScrapyTutorial-master\tutorial\pipelines.py", line 36, in process_item
    self.db[name].insert(dict(item))
  File "c:\users\w\anaconda3\lib\site-packages\pymongo\collection.py", line 3182, in insert
    check_keys, manipulate, write_concern)
  File "c:\users\w\anaconda3\lib\site-packages\pymongo\collection.py", line 612, in _insert
    bypass_doc_val, session)
  File "c:\users\w\anaconda3\lib\site-packages\pymongo\collection.py", line 600, in _insert_one
    acknowledged, _insert_command, session)
  File "c:\users\w\anaconda3\lib\site-packages\pymongo\mongo_client.py", line 1491, in _retryable_write
    with self._tmp_session(session) as s:
  File "c:\users\w\anaconda3\lib\contextlib.py", line 59, in __enter__
    return next(self.gen)
  File "c:\users\w\anaconda3\lib\site-packages\pymongo\mongo_client.py", line 1820, in _tmp_session
    s = self._ensure_session(session)
  File "c:\users\w\anaconda3\lib\site-packages\pymongo\mongo_client.py", line 1807, in _ensure_session
    return self.__start_session(True, causal_consistency=False)
  File "c:\users\w\anaconda3\lib\site-packages\pymongo\mongo_client.py", line 1760, in __start_session
    server_session = self._get_server_session()
  File "c:\users\w\anaconda3\lib\site-packages\pymongo\mongo_client.py", line 1793, in _get_server_session
    return self._topology.get_server_session()
  File "c:\users\w\anaconda3\lib\site-packages\pymongo\topology.py", line 477, in get_server_session
    None)
  File "c:\users\w\anaconda3\lib\site-packages\pymongo\topology.py", line 205, in _select_servers_loop
    self._error_message(selector))
pymongo.errors.ServerSelectionTimeoutError: localhost:27017: [WinError 10061] 由于目标计算机积极拒绝，无法连接。
2020-03-26 11:15:05 [scrapy] ERROR: Error processing {'author': 'Douglas Adams',
 'tags': ['life', 'navigation'],
 'text': '“I may not have gone where I intended to go, but I...'}
Traceback (most recent call last):
  File "c:\users\w\anaconda3\lib\site-packages\twisted\internet\defer.py", line 654, in _runCallbacks
    current.result = callback(current.result, *args, **kw)
  File "c:\users\w\anaconda3\lib\site-packages\scrapy\utils\defer.py", line 154, in f
    return deferred_from_coro(coro_f(*coro_args, **coro_kwargs))
  File "E:\scrapy\ScrapyTutorial-master\tutorial\pipelines.py", line 36, in process_item
    self.db[name].insert(dict(item))
  File "c:\users\w\anaconda3\lib\site-packages\pymongo\collection.py", line 3182, in insert
    check_keys, manipulate, write_concern)
  File "c:\users\w\anaconda3\lib\site-packages\pymongo\collection.py", line 612, in _insert
    bypass_doc_val, session)
  File "c:\users\w\anaconda3\lib\site-packages\pymongo\collection.py", line 600, in _insert_one
    acknowledged, _insert_command, session)
  File "c:\users\w\anaconda3\lib\site-packages\pymongo\mongo_client.py", line 1491, in _retryable_write
    with self._tmp_session(session) as s:
  File "c:\users\w\anaconda3\lib\contextlib.py", line 59, in __enter__
    return next(self.gen)
  File "c:\users\w\anaconda3\lib\site-packages\pymongo\mongo_client.py", line 1820, in _tmp_session
    s = self._ensure_session(session)
  File "c:\users\w\anaconda3\lib\site-packages\pymongo\mongo_client.py", line 1807, in _ensure_session
    return self.__start_session(True, causal_consistency=False)
  File "c:\users\w\anaconda3\lib\site-packages\pymongo\mongo_client.py", line 1760, in __start_session
    server_session = self._get_server_session()
  File "c:\users\w\anaconda3\lib\site-packages\pymongo\mongo_client.py", line 1793, in _get_server_session
    return self._topology.get_server_session()
  File "c:\users\w\anaconda3\lib\site-packages\pymongo\topology.py", line 477, in get_server_session
    None)
  File "c:\users\w\anaconda3\lib\site-packages\pymongo\topology.py", line 205, in _select_servers_loop
    self._error_message(selector))
pymongo.errors.ServerSelectionTimeoutError: localhost:27017: [WinError 10061] 由于目标计算机积极拒绝，无法连接。
2020-03-26 11:15:35 [scrapy] ERROR: Error processing {'author': 'Elie Wiesel',
 'tags': ['activism',
          'apathy',
          'hate',
          'indifference',
          'inspirational',
          'love',
          'opposite',
          'philosophy'],
 'text': "“The opposite of love is not hate, it's indifferen..."}
Traceback (most recent call last):
  File "c:\users\w\anaconda3\lib\site-packages\twisted\internet\defer.py", line 654, in _runCallbacks
    current.result = callback(current.result, *args, **kw)
  File "c:\users\w\anaconda3\lib\site-packages\scrapy\utils\defer.py", line 154, in f
    return deferred_from_coro(coro_f(*coro_args, **coro_kwargs))
  File "E:\scrapy\ScrapyTutorial-master\tutorial\pipelines.py", line 36, in process_item
    self.db[name].insert(dict(item))
  File "c:\users\w\anaconda3\lib\site-packages\pymongo\collection.py", line 3182, in insert
    check_keys, manipulate, write_concern)
  File "c:\users\w\anaconda3\lib\site-packages\pymongo\collection.py", line 612, in _insert
    bypass_doc_val, session)
  File "c:\users\w\anaconda3\lib\site-packages\pymongo\collection.py", line 600, in _insert_one
    acknowledged, _insert_command, session)
  File "c:\users\w\anaconda3\lib\site-packages\pymongo\mongo_client.py", line 1491, in _retryable_write
    with self._tmp_session(session) as s:
  File "c:\users\w\anaconda3\lib\contextlib.py", line 59, in __enter__
    return next(self.gen)
  File "c:\users\w\anaconda3\lib\site-packages\pymongo\mongo_client.py", line 1820, in _tmp_session
    s = self._ensure_session(session)
  File "c:\users\w\anaconda3\lib\site-packages\pymongo\mongo_client.py", line 1807, in _ensure_session
    return self.__start_session(True, causal_consistency=False)
  File "c:\users\w\anaconda3\lib\site-packages\pymongo\mongo_client.py", line 1760, in __start_session
    server_session = self._get_server_session()
  File "c:\users\w\anaconda3\lib\site-packages\pymongo\mongo_client.py", line 1793, in _get_server_session
    return self._topology.get_server_session()
  File "c:\users\w\anaconda3\lib\site-packages\pymongo\topology.py", line 477, in get_server_session
    None)
  File "c:\users\w\anaconda3\lib\site-packages\pymongo\topology.py", line 205, in _select_servers_loop
    self._error_message(selector))
pymongo.errors.ServerSelectionTimeoutError: localhost:27017: [WinError 10061] 由于目标计算机积极拒绝，无法连接。
2020-03-26 11:16:05 [scrapy] ERROR: Error processing {'author': 'Friedrich Nietzsche',
 'tags': ['friendship',
          'lack-of-friendship',
          'lack-of-love',
          'love',
          'marriage',
          'unhappy-marriage'],
 'text': '“It is not a lack of love, but a lack of friendshi...'}
Traceback (most recent call last):
  File "c:\users\w\anaconda3\lib\site-packages\twisted\internet\defer.py", line 654, in _runCallbacks
    current.result = callback(current.result, *args, **kw)
  File "c:\users\w\anaconda3\lib\site-packages\scrapy\utils\defer.py", line 154, in f
    return deferred_from_coro(coro_f(*coro_args, **coro_kwargs))
  File "E:\scrapy\ScrapyTutorial-master\tutorial\pipelines.py", line 36, in process_item
    self.db[name].insert(dict(item))
  File "c:\users\w\anaconda3\lib\site-packages\pymongo\collection.py", line 3182, in insert
    check_keys, manipulate, write_concern)
  File "c:\users\w\anaconda3\lib\site-packages\pymongo\collection.py", line 612, in _insert
    bypass_doc_val, session)
  File "c:\users\w\anaconda3\lib\site-packages\pymongo\collection.py", line 600, in _insert_one
    acknowledged, _insert_command, session)
  File "c:\users\w\anaconda3\lib\site-packages\pymongo\mongo_client.py", line 1491, in _retryable_write
    with self._tmp_session(session) as s:
  File "c:\users\w\anaconda3\lib\contextlib.py", line 59, in __enter__
    return next(self.gen)
  File "c:\users\w\anaconda3\lib\site-packages\pymongo\mongo_client.py", line 1820, in _tmp_session
    s = self._ensure_session(session)
  File "c:\users\w\anaconda3\lib\site-packages\pymongo\mongo_client.py", line 1807, in _ensure_session
    return self.__start_session(True, causal_consistency=False)
  File "c:\users\w\anaconda3\lib\site-packages\pymongo\mongo_client.py", line 1760, in __start_session
    server_session = self._get_server_session()
  File "c:\users\w\anaconda3\lib\site-packages\pymongo\mongo_client.py", line 1793, in _get_server_session
    return self._topology.get_server_session()
  File "c:\users\w\anaconda3\lib\site-packages\pymongo\topology.py", line 477, in get_server_session
    None)
  File "c:\users\w\anaconda3\lib\site-packages\pymongo\topology.py", line 205, in _select_servers_loop
    self._error_message(selector))
pymongo.errors.ServerSelectionTimeoutError: localhost:27017: [WinError 10061] 由于目标计算机积极拒绝，无法连接。
2020-03-26 11:16:35 [scrapy] ERROR: Error processing {'author': 'Mark Twain',
 'tags': ['books', 'contentment', 'friends', 'friendship', 'life'],
 'text': '“Good friends, good books, and a sleepy conscience...'}
Traceback (most recent call last):
  File "c:\users\w\anaconda3\lib\site-packages\twisted\internet\defer.py", line 654, in _runCallbacks
    current.result = callback(current.result, *args, **kw)
  File "c:\users\w\anaconda3\lib\site-packages\scrapy\utils\defer.py", line 154, in f
    return deferred_from_coro(coro_f(*coro_args, **coro_kwargs))
  File "E:\scrapy\ScrapyTutorial-master\tutorial\pipelines.py", line 36, in process_item
    self.db[name].insert(dict(item))
  File "c:\users\w\anaconda3\lib\site-packages\pymongo\collection.py", line 3182, in insert
    check_keys, manipulate, write_concern)
  File "c:\users\w\anaconda3\lib\site-packages\pymongo\collection.py", line 612, in _insert
    bypass_doc_val, session)
  File "c:\users\w\anaconda3\lib\site-packages\pymongo\collection.py", line 600, in _insert_one
    acknowledged, _insert_command, session)
  File "c:\users\w\anaconda3\lib\site-packages\pymongo\mongo_client.py", line 1491, in _retryable_write
    with self._tmp_session(session) as s:
  File "c:\users\w\anaconda3\lib\contextlib.py", line 59, in __enter__
    return next(self.gen)
  File "c:\users\w\anaconda3\lib\site-packages\pymongo\mongo_client.py", line 1820, in _tmp_session
    s = self._ensure_session(session)
  File "c:\users\w\anaconda3\lib\site-packages\pymongo\mongo_client.py", line 1807, in _ensure_session
    return self.__start_session(True, causal_consistency=False)
  File "c:\users\w\anaconda3\lib\site-packages\pymongo\mongo_client.py", line 1760, in __start_session
    server_session = self._get_server_session()
  File "c:\users\w\anaconda3\lib\site-packages\pymongo\mongo_client.py", line 1793, in _get_server_session
    return self._topology.get_server_session()
  File "c:\users\w\anaconda3\lib\site-packages\pymongo\topology.py", line 477, in get_server_session
    None)
  File "c:\users\w\anaconda3\lib\site-packages\pymongo\topology.py", line 205, in _select_servers_loop
    self._error_message(selector))
pymongo.errors.ServerSelectionTimeoutError: localhost:27017: [WinError 10061] 由于目标计算机积极拒绝，无法连接。
2020-03-26 11:17:06 [scrapy] ERROR: Error processing {'author': 'Allen Saunders',
 'tags': ['fate', 'life', 'misattributed-john-lennon', 'planning', 'plans'],
 'text': '“Life is what happens to us while we are making ot...'}
Traceback (most recent call last):
  File "c:\users\w\anaconda3\lib\site-packages\twisted\internet\defer.py", line 654, in _runCallbacks
    current.result = callback(current.result, *args, **kw)
  File "c:\users\w\anaconda3\lib\site-packages\scrapy\utils\defer.py", line 154, in f
    return deferred_from_coro(coro_f(*coro_args, **coro_kwargs))
  File "E:\scrapy\ScrapyTutorial-master\tutorial\pipelines.py", line 36, in process_item
    self.db[name].insert(dict(item))
  File "c:\users\w\anaconda3\lib\site-packages\pymongo\collection.py", line 3182, in insert
    check_keys, manipulate, write_concern)
  File "c:\users\w\anaconda3\lib\site-packages\pymongo\collection.py", line 612, in _insert
    bypass_doc_val, session)
  File "c:\users\w\anaconda3\lib\site-packages\pymongo\collection.py", line 600, in _insert_one
    acknowledged, _insert_command, session)
  File "c:\users\w\anaconda3\lib\site-packages\pymongo\mongo_client.py", line 1491, in _retryable_write
    with self._tmp_session(session) as s:
  File "c:\users\w\anaconda3\lib\contextlib.py", line 59, in __enter__
    return next(self.gen)
  File "c:\users\w\anaconda3\lib\site-packages\pymongo\mongo_client.py", line 1820, in _tmp_session
    s = self._ensure_session(session)
  File "c:\users\w\anaconda3\lib\site-packages\pymongo\mongo_client.py", line 1807, in _ensure_session
    return self.__start_session(True, causal_consistency=False)
  File "c:\users\w\anaconda3\lib\site-packages\pymongo\mongo_client.py", line 1760, in __start_session
    server_session = self._get_server_session()
  File "c:\users\w\anaconda3\lib\site-packages\pymongo\mongo_client.py", line 1793, in _get_server_session
    return self._topology.get_server_session()
  File "c:\users\w\anaconda3\lib\site-packages\pymongo\topology.py", line 477, in get_server_session
    None)
  File "c:\users\w\anaconda3\lib\site-packages\pymongo\topology.py", line 205, in _select_servers_loop
    self._error_message(selector))
pymongo.errors.ServerSelectionTimeoutError: localhost:27017: [WinError 10061] 由于目标计算机积极拒绝，无法连接。
2020-03-26 11:19:23 [scrapy] DEBUG: Crawled (200) <GET http://quotes.toscrape.com/page/3/> (referer: http://quotes.toscrape.com/page/2/)
2020-03-26 11:19:53 [scrapy] ERROR: Error processing {'author': 'Pablo Neruda',
 'tags': ['love', 'poetry'],
 'text': '“I love you without knowing how, or when, or from...'}
Traceback (most recent call last):
  File "c:\users\w\anaconda3\lib\site-packages\twisted\internet\defer.py", line 654, in _runCallbacks
    current.result = callback(current.result, *args, **kw)
  File "c:\users\w\anaconda3\lib\site-packages\scrapy\utils\defer.py", line 154, in f
    return deferred_from_coro(coro_f(*coro_args, **coro_kwargs))
  File "E:\scrapy\ScrapyTutorial-master\tutorial\pipelines.py", line 36, in process_item
    self.db[name].insert(dict(item))
  File "c:\users\w\anaconda3\lib\site-packages\pymongo\collection.py", line 3182, in insert
    check_keys, manipulate, write_concern)
  File "c:\users\w\anaconda3\lib\site-packages\pymongo\collection.py", line 612, in _insert
    bypass_doc_val, session)
  File "c:\users\w\anaconda3\lib\site-packages\pymongo\collection.py", line 600, in _insert_one
    acknowledged, _insert_command, session)
  File "c:\users\w\anaconda3\lib\site-packages\pymongo\mongo_client.py", line 1491, in _retryable_write
    with self._tmp_session(session) as s:
  File "c:\users\w\anaconda3\lib\contextlib.py", line 59, in __enter__
    return next(self.gen)
  File "c:\users\w\anaconda3\lib\site-packages\pymongo\mongo_client.py", line 1820, in _tmp_session
    s = self._ensure_session(session)
  File "c:\users\w\anaconda3\lib\site-packages\pymongo\mongo_client.py", line 1807, in _ensure_session
    return self.__start_session(True, causal_consistency=False)
  File "c:\users\w\anaconda3\lib\site-packages\pymongo\mongo_client.py", line 1760, in __start_session
    server_session = self._get_server_session()
  File "c:\users\w\anaconda3\lib\site-packages\pymongo\mongo_client.py", line 1793, in _get_server_session
    return self._topology.get_server_session()
  File "c:\users\w\anaconda3\lib\site-packages\pymongo\topology.py", line 477, in get_server_session
    None)
  File "c:\users\w\anaconda3\lib\site-packages\pymongo\topology.py", line 205, in _select_servers_loop
    self._error_message(selector))
pymongo.errors.ServerSelectionTimeoutError: localhost:27017: [WinError 10061] 由于目标计算机积极拒绝，无法连接。
2020-03-26 11:20:24 [scrapy] ERROR: Error processing {'author': 'Ralph Waldo Emerson',
 'tags': ['happiness'],
 'text': '“For every minute you are angry you lose sixty sec...'}
Traceback (most recent call last):
  File "c:\users\w\anaconda3\lib\site-packages\twisted\internet\defer.py", line 654, in _runCallbacks
    current.result = callback(current.result, *args, **kw)
  File "c:\users\w\anaconda3\lib\site-packages\scrapy\utils\defer.py", line 154, in f
    return deferred_from_coro(coro_f(*coro_args, **coro_kwargs))
  File "E:\scrapy\ScrapyTutorial-master\tutorial\pipelines.py", line 36, in process_item
    self.db[name].insert(dict(item))
  File "c:\users\w\anaconda3\lib\site-packages\pymongo\collection.py", line 3182, in insert
    check_keys, manipulate, write_concern)
  File "c:\users\w\anaconda3\lib\site-packages\pymongo\collection.py", line 612, in _insert
    bypass_doc_val, session)
  File "c:\users\w\anaconda3\lib\site-packages\pymongo\collection.py", line 600, in _insert_one
    acknowledged, _insert_command, session)
  File "c:\users\w\anaconda3\lib\site-packages\pymongo\mongo_client.py", line 1491, in _retryable_write
    with self._tmp_session(session) as s:
  File "c:\users\w\anaconda3\lib\contextlib.py", line 59, in __enter__
    return next(self.gen)
  File "c:\users\w\anaconda3\lib\site-packages\pymongo\mongo_client.py", line 1820, in _tmp_session
    s = self._ensure_session(session)
  File "c:\users\w\anaconda3\lib\site-packages\pymongo\mongo_client.py", line 1807, in _ensure_session
    return self.__start_session(True, causal_consistency=False)
  File "c:\users\w\anaconda3\lib\site-packages\pymongo\mongo_client.py", line 1760, in __start_session
    server_session = self._get_server_session()
  File "c:\users\w\anaconda3\lib\site-packages\pymongo\mongo_client.py", line 1793, in _get_server_session
    return self._topology.get_server_session()
  File "c:\users\w\anaconda3\lib\site-packages\pymongo\topology.py", line 477, in get_server_session
    None)
  File "c:\users\w\anaconda3\lib\site-packages\pymongo\topology.py", line 205, in _select_servers_loop
    self._error_message(selector))
pymongo.errors.ServerSelectionTimeoutError: localhost:27017: [WinError 10061] 由于目标计算机积极拒绝，无法连接。
2020-03-26 11:20:54 [scrapy] ERROR: Error processing {'author': 'Mother Teresa',
 'tags': ['attributed-no-source'],
 'text': '“If you judge people, you have no time to love the...'}
Traceback (most recent call last):
  File "c:\users\w\anaconda3\lib\site-packages\twisted\internet\defer.py", line 654, in _runCallbacks
    current.result = callback(current.result, *args, **kw)
  File "c:\users\w\anaconda3\lib\site-packages\scrapy\utils\defer.py", line 154, in f
    return deferred_from_coro(coro_f(*coro_args, **coro_kwargs))
  File "E:\scrapy\ScrapyTutorial-master\tutorial\pipelines.py", line 36, in process_item
    self.db[name].insert(dict(item))
  File "c:\users\w\anaconda3\lib\site-packages\pymongo\collection.py", line 3182, in insert
    check_keys, manipulate, write_concern)
  File "c:\users\w\anaconda3\lib\site-packages\pymongo\collection.py", line 612, in _insert
    bypass_doc_val, session)
  File "c:\users\w\anaconda3\lib\site-packages\pymongo\collection.py", line 600, in _insert_one
    acknowledged, _insert_command, session)
  File "c:\users\w\anaconda3\lib\site-packages\pymongo\mongo_client.py", line 1491, in _retryable_write
    with self._tmp_session(session) as s:
  File "c:\users\w\anaconda3\lib\contextlib.py", line 59, in __enter__
    return next(self.gen)
  File "c:\users\w\anaconda3\lib\site-packages\pymongo\mongo_client.py", line 1820, in _tmp_session
    s = self._ensure_session(session)
  File "c:\users\w\anaconda3\lib\site-packages\pymongo\mongo_client.py", line 1807, in _ensure_session
    return self.__start_session(True, causal_consistency=False)
  File "c:\users\w\anaconda3\lib\site-packages\pymongo\mongo_client.py", line 1760, in __start_session
    server_session = self._get_server_session()
  File "c:\users\w\anaconda3\lib\site-packages\pymongo\mongo_client.py", line 1793, in _get_server_session
    return self._topology.get_server_session()
  File "c:\users\w\anaconda3\lib\site-packages\pymongo\topology.py", line 477, in get_server_session
    None)
  File "c:\users\w\anaconda3\lib\site-packages\pymongo\topology.py", line 205, in _select_servers_loop
    self._error_message(selector))
pymongo.errors.ServerSelectionTimeoutError: localhost:27017: [WinError 10061] 由于目标计算机积极拒绝，无法连接。
2020-03-26 11:21:24 [scrapy] ERROR: Error processing {'author': 'Garrison Keillor',
 'tags': ['humor', 'religion'],
 'text': '“Anyone who thinks sitting in church can make you...'}
Traceback (most recent call last):
  File "c:\users\w\anaconda3\lib\site-packages\twisted\internet\defer.py", line 654, in _runCallbacks
    current.result = callback(current.result, *args, **kw)
  File "c:\users\w\anaconda3\lib\site-packages\scrapy\utils\defer.py", line 154, in f
    return deferred_from_coro(coro_f(*coro_args, **coro_kwargs))
  File "E:\scrapy\ScrapyTutorial-master\tutorial\pipelines.py", line 36, in process_item
    self.db[name].insert(dict(item))
  File "c:\users\w\anaconda3\lib\site-packages\pymongo\collection.py", line 3182, in insert
    check_keys, manipulate, write_concern)
  File "c:\users\w\anaconda3\lib\site-packages\pymongo\collection.py", line 612, in _insert
    bypass_doc_val, session)
  File "c:\users\w\anaconda3\lib\site-packages\pymongo\collection.py", line 600, in _insert_one
    acknowledged, _insert_command, session)
  File "c:\users\w\anaconda3\lib\site-packages\pymongo\mongo_client.py", line 1491, in _retryable_write
    with self._tmp_session(session) as s:
  File "c:\users\w\anaconda3\lib\contextlib.py", line 59, in __enter__
    return next(self.gen)
  File "c:\users\w\anaconda3\lib\site-packages\pymongo\mongo_client.py", line 1820, in _tmp_session
    s = self._ensure_session(session)
  File "c:\users\w\anaconda3\lib\site-packages\pymongo\mongo_client.py", line 1807, in _ensure_session
    return self.__start_session(True, causal_consistency=False)
  File "c:\users\w\anaconda3\lib\site-packages\pymongo\mongo_client.py", line 1760, in __start_session
    server_session = self._get_server_session()
  File "c:\users\w\anaconda3\lib\site-packages\pymongo\mongo_client.py", line 1793, in _get_server_session
    return self._topology.get_server_session()
  File "c:\users\w\anaconda3\lib\site-packages\pymongo\topology.py", line 477, in get_server_session
    None)
  File "c:\users\w\anaconda3\lib\site-packages\pymongo\topology.py", line 205, in _select_servers_loop
    self._error_message(selector))
pymongo.errors.ServerSelectionTimeoutError: localhost:27017: [WinError 10061] 由于目标计算机积极拒绝，无法连接。
2020-03-26 11:21:54 [scrapy] ERROR: Error processing {'author': 'Jim Henson',
 'tags': ['humor'],
 'text': '“Beauty is in the eye of the beholder and it may b...'}
Traceback (most recent call last):
  File "c:\users\w\anaconda3\lib\site-packages\twisted\internet\defer.py", line 654, in _runCallbacks
    current.result = callback(current.result, *args, **kw)
  File "c:\users\w\anaconda3\lib\site-packages\scrapy\utils\defer.py", line 154, in f
    return deferred_from_coro(coro_f(*coro_args, **coro_kwargs))
  File "E:\scrapy\ScrapyTutorial-master\tutorial\pipelines.py", line 36, in process_item
    self.db[name].insert(dict(item))
  File "c:\users\w\anaconda3\lib\site-packages\pymongo\collection.py", line 3182, in insert
    check_keys, manipulate, write_concern)
  File "c:\users\w\anaconda3\lib\site-packages\pymongo\collection.py", line 612, in _insert
    bypass_doc_val, session)
  File "c:\users\w\anaconda3\lib\site-packages\pymongo\collection.py", line 600, in _insert_one
    acknowledged, _insert_command, session)
  File "c:\users\w\anaconda3\lib\site-packages\pymongo\mongo_client.py", line 1491, in _retryable_write
    with self._tmp_session(session) as s:
  File "c:\users\w\anaconda3\lib\contextlib.py", line 59, in __enter__
    return next(self.gen)
  File "c:\users\w\anaconda3\lib\site-packages\pymongo\mongo_client.py", line 1820, in _tmp_session
    s = self._ensure_session(session)
  File "c:\users\w\anaconda3\lib\site-packages\pymongo\mongo_client.py", line 1807, in _ensure_session
    return self.__start_session(True, causal_consistency=False)
  File "c:\users\w\anaconda3\lib\site-packages\pymongo\mongo_client.py", line 1760, in __start_session
    server_session = self._get_server_session()
  File "c:\users\w\anaconda3\lib\site-packages\pymongo\mongo_client.py", line 1793, in _get_server_session
    return self._topology.get_server_session()
  File "c:\users\w\anaconda3\lib\site-packages\pymongo\topology.py", line 477, in get_server_session
    None)
  File "c:\users\w\anaconda3\lib\site-packages\pymongo\topology.py", line 205, in _select_servers_loop
    self._error_message(selector))
pymongo.errors.ServerSelectionTimeoutError: localhost:27017: [WinError 10061] 由于目标计算机积极拒绝，无法连接。
2020-03-26 11:22:24 [scrapy] ERROR: Error processing {'author': 'Dr. Seuss',
 'tags': ['comedy', 'life', 'yourself'],
 'text': '“Today you are You, that is truer than true. There...'}
Traceback (most recent call last):
  File "c:\users\w\anaconda3\lib\site-packages\twisted\internet\defer.py", line 654, in _runCallbacks
    current.result = callback(current.result, *args, **kw)
  File "c:\users\w\anaconda3\lib\site-packages\scrapy\utils\defer.py", line 154, in f
    return deferred_from_coro(coro_f(*coro_args, **coro_kwargs))
  File "E:\scrapy\ScrapyTutorial-master\tutorial\pipelines.py", line 36, in process_item
    self.db[name].insert(dict(item))
  File "c:\users\w\anaconda3\lib\site-packages\pymongo\collection.py", line 3182, in insert
    check_keys, manipulate, write_concern)
  File "c:\users\w\anaconda3\lib\site-packages\pymongo\collection.py", line 612, in _insert
    bypass_doc_val, session)
  File "c:\users\w\anaconda3\lib\site-packages\pymongo\collection.py", line 600, in _insert_one
    acknowledged, _insert_command, session)
  File "c:\users\w\anaconda3\lib\site-packages\pymongo\mongo_client.py", line 1491, in _retryable_write
    with self._tmp_session(session) as s:
  File "c:\users\w\anaconda3\lib\contextlib.py", line 59, in __enter__
    return next(self.gen)
  File "c:\users\w\anaconda3\lib\site-packages\pymongo\mongo_client.py", line 1820, in _tmp_session
    s = self._ensure_session(session)
  File "c:\users\w\anaconda3\lib\site-packages\pymongo\mongo_client.py", line 1807, in _ensure_session
    return self.__start_session(True, causal_consistency=False)
  File "c:\users\w\anaconda3\lib\site-packages\pymongo\mongo_client.py", line 1760, in __start_session
    server_session = self._get_server_session()
  File "c:\users\w\anaconda3\lib\site-packages\pymongo\mongo_client.py", line 1793, in _get_server_session
    return self._topology.get_server_session()
  File "c:\users\w\anaconda3\lib\site-packages\pymongo\topology.py", line 477, in get_server_session
    None)
  File "c:\users\w\anaconda3\lib\site-packages\pymongo\topology.py", line 205, in _select_servers_loop
    self._error_message(selector))
pymongo.errors.ServerSelectionTimeoutError: localhost:27017: [WinError 10061] 由于目标计算机积极拒绝，无法连接。
2020-03-26 11:22:54 [scrapy] ERROR: Error processing {'author': 'Albert Einstein',
 'tags': ['children', 'fairy-tales'],
 'text': '“If you want your children to be intelligent, read...'}
Traceback (most recent call last):
  File "c:\users\w\anaconda3\lib\site-packages\twisted\internet\defer.py", line 654, in _runCallbacks
    current.result = callback(current.result, *args, **kw)
  File "c:\users\w\anaconda3\lib\site-packages\scrapy\utils\defer.py", line 154, in f
    return deferred_from_coro(coro_f(*coro_args, **coro_kwargs))
  File "E:\scrapy\ScrapyTutorial-master\tutorial\pipelines.py", line 36, in process_item
    self.db[name].insert(dict(item))
  File "c:\users\w\anaconda3\lib\site-packages\pymongo\collection.py", line 3182, in insert
    check_keys, manipulate, write_concern)
  File "c:\users\w\anaconda3\lib\site-packages\pymongo\collection.py", line 612, in _insert
    bypass_doc_val, session)
  File "c:\users\w\anaconda3\lib\site-packages\pymongo\collection.py", line 600, in _insert_one
    acknowledged, _insert_command, session)
  File "c:\users\w\anaconda3\lib\site-packages\pymongo\mongo_client.py", line 1491, in _retryable_write
    with self._tmp_session(session) as s:
  File "c:\users\w\anaconda3\lib\contextlib.py", line 59, in __enter__
    return next(self.gen)
  File "c:\users\w\anaconda3\lib\site-packages\pymongo\mongo_client.py", line 1820, in _tmp_session
    s = self._ensure_session(session)
  File "c:\users\w\anaconda3\lib\site-packages\pymongo\mongo_client.py", line 1807, in _ensure_session
    return self.__start_session(True, causal_consistency=False)
  File "c:\users\w\anaconda3\lib\site-packages\pymongo\mongo_client.py", line 1760, in __start_session
    server_session = self._get_server_session()
  File "c:\users\w\anaconda3\lib\site-packages\pymongo\mongo_client.py", line 1793, in _get_server_session
    return self._topology.get_server_session()
  File "c:\users\w\anaconda3\lib\site-packages\pymongo\topology.py", line 477, in get_server_session
    None)
  File "c:\users\w\anaconda3\lib\site-packages\pymongo\topology.py", line 205, in _select_servers_loop
    self._error_message(selector))
pymongo.errors.ServerSelectionTimeoutError: localhost:27017: [WinError 10061] 由于目标计算机积极拒绝，无法连接。
2020-03-26 11:23:24 [scrapy] ERROR: Error processing {'author': 'J.K. Rowling',
 'tags': [],
 'text': '“It is impossible to live without failing at somet...'}
Traceback (most recent call last):
  File "c:\users\w\anaconda3\lib\site-packages\twisted\internet\defer.py", line 654, in _runCallbacks
    current.result = callback(current.result, *args, **kw)
  File "c:\users\w\anaconda3\lib\site-packages\scrapy\utils\defer.py", line 154, in f
    return deferred_from_coro(coro_f(*coro_args, **coro_kwargs))
  File "E:\scrapy\ScrapyTutorial-master\tutorial\pipelines.py", line 36, in process_item
    self.db[name].insert(dict(item))
  File "c:\users\w\anaconda3\lib\site-packages\pymongo\collection.py", line 3182, in insert
    check_keys, manipulate, write_concern)
  File "c:\users\w\anaconda3\lib\site-packages\pymongo\collection.py", line 612, in _insert
    bypass_doc_val, session)
  File "c:\users\w\anaconda3\lib\site-packages\pymongo\collection.py", line 600, in _insert_one
    acknowledged, _insert_command, session)
  File "c:\users\w\anaconda3\lib\site-packages\pymongo\mongo_client.py", line 1491, in _retryable_write
    with self._tmp_session(session) as s:
  File "c:\users\w\anaconda3\lib\contextlib.py", line 59, in __enter__
    return next(self.gen)
  File "c:\users\w\anaconda3\lib\site-packages\pymongo\mongo_client.py", line 1820, in _tmp_session
    s = self._ensure_session(session)
  File "c:\users\w\anaconda3\lib\site-packages\pymongo\mongo_client.py", line 1807, in _ensure_session
    return self.__start_session(True, causal_consistency=False)
  File "c:\users\w\anaconda3\lib\site-packages\pymongo\mongo_client.py", line 1760, in __start_session
    server_session = self._get_server_session()
  File "c:\users\w\anaconda3\lib\site-packages\pymongo\mongo_client.py", line 1793, in _get_server_session
    return self._topology.get_server_session()
  File "c:\users\w\anaconda3\lib\site-packages\pymongo\topology.py", line 477, in get_server_session
    None)
  File "c:\users\w\anaconda3\lib\site-packages\pymongo\topology.py", line 205, in _select_servers_loop
    self._error_message(selector))
pymongo.errors.ServerSelectionTimeoutError: localhost:27017: [WinError 10061] 由于目标计算机积极拒绝，无法连接。
2020-03-26 11:23:54 [scrapy] ERROR: Error processing {'author': 'Albert Einstein',
 'tags': ['imagination'],
 'text': '“Logic will get you from A to Z; imagination will...'}
Traceback (most recent call last):
  File "c:\users\w\anaconda3\lib\site-packages\twisted\internet\defer.py", line 654, in _runCallbacks
    current.result = callback(current.result, *args, **kw)
  File "c:\users\w\anaconda3\lib\site-packages\scrapy\utils\defer.py", line 154, in f
    return deferred_from_coro(coro_f(*coro_args, **coro_kwargs))
  File "E:\scrapy\ScrapyTutorial-master\tutorial\pipelines.py", line 36, in process_item
    self.db[name].insert(dict(item))
  File "c:\users\w\anaconda3\lib\site-packages\pymongo\collection.py", line 3182, in insert
    check_keys, manipulate, write_concern)
  File "c:\users\w\anaconda3\lib\site-packages\pymongo\collection.py", line 612, in _insert
    bypass_doc_val, session)
  File "c:\users\w\anaconda3\lib\site-packages\pymongo\collection.py", line 600, in _insert_one
    acknowledged, _insert_command, session)
  File "c:\users\w\anaconda3\lib\site-packages\pymongo\mongo_client.py", line 1491, in _retryable_write
    with self._tmp_session(session) as s:
  File "c:\users\w\anaconda3\lib\contextlib.py", line 59, in __enter__
    return next(self.gen)
  File "c:\users\w\anaconda3\lib\site-packages\pymongo\mongo_client.py", line 1820, in _tmp_session
    s = self._ensure_session(session)
  File "c:\users\w\anaconda3\lib\site-packages\pymongo\mongo_client.py", line 1807, in _ensure_session
    return self.__start_session(True, causal_consistency=False)
  File "c:\users\w\anaconda3\lib\site-packages\pymongo\mongo_client.py", line 1760, in __start_session
    server_session = self._get_server_session()
  File "c:\users\w\anaconda3\lib\site-packages\pymongo\mongo_client.py", line 1793, in _get_server_session
    return self._topology.get_server_session()
  File "c:\users\w\anaconda3\lib\site-packages\pymongo\topology.py", line 477, in get_server_session
    None)
  File "c:\users\w\anaconda3\lib\site-packages\pymongo\topology.py", line 205, in _select_servers_loop
    self._error_message(selector))
pymongo.errors.ServerSelectionTimeoutError: localhost:27017: [WinError 10061] 由于目标计算机积极拒绝，无法连接。
2020-03-26 11:24:24 [scrapy] ERROR: Error processing {'author': 'Bob Marley',
 'tags': ['music'],
 'text': '“One good thing about music, when it hits you, you...'}
Traceback (most recent call last):
  File "c:\users\w\anaconda3\lib\site-packages\twisted\internet\defer.py", line 654, in _runCallbacks
    current.result = callback(current.result, *args, **kw)
  File "c:\users\w\anaconda3\lib\site-packages\scrapy\utils\defer.py", line 154, in f
    return deferred_from_coro(coro_f(*coro_args, **coro_kwargs))
  File "E:\scrapy\ScrapyTutorial-master\tutorial\pipelines.py", line 36, in process_item
    self.db[name].insert(dict(item))
  File "c:\users\w\anaconda3\lib\site-packages\pymongo\collection.py", line 3182, in insert
    check_keys, manipulate, write_concern)
  File "c:\users\w\anaconda3\lib\site-packages\pymongo\collection.py", line 612, in _insert
    bypass_doc_val, session)
  File "c:\users\w\anaconda3\lib\site-packages\pymongo\collection.py", line 600, in _insert_one
    acknowledged, _insert_command, session)
  File "c:\users\w\anaconda3\lib\site-packages\pymongo\mongo_client.py", line 1491, in _retryable_write
    with self._tmp_session(session) as s:
  File "c:\users\w\anaconda3\lib\contextlib.py", line 59, in __enter__
    return next(self.gen)
  File "c:\users\w\anaconda3\lib\site-packages\pymongo\mongo_client.py", line 1820, in _tmp_session
    s = self._ensure_session(session)
  File "c:\users\w\anaconda3\lib\site-packages\pymongo\mongo_client.py", line 1807, in _ensure_session
    return self.__start_session(True, causal_consistency=False)
  File "c:\users\w\anaconda3\lib\site-packages\pymongo\mongo_client.py", line 1760, in __start_session
    server_session = self._get_server_session()
  File "c:\users\w\anaconda3\lib\site-packages\pymongo\mongo_client.py", line 1793, in _get_server_session
    return self._topology.get_server_session()
  File "c:\users\w\anaconda3\lib\site-packages\pymongo\topology.py", line 477, in get_server_session
    None)
  File "c:\users\w\anaconda3\lib\site-packages\pymongo\topology.py", line 205, in _select_servers_loop
    self._error_message(selector))
pymongo.errors.ServerSelectionTimeoutError: localhost:27017: [WinError 10061] 由于目标计算机积极拒绝，无法连接。
2020-03-26 11:24:24 [scrapy] INFO: Closing spider (timeout)
2020-03-26 11:24:24 [scrapy] INFO: Dumping Scrapy stats:
{'downloader/request_bytes': 999,
 'downloader/request_count': 4,
 'downloader/request_method_count/GET': 4,
 'downloader/response_bytes': 8323,
 'downloader/response_count': 4,
 'downloader/response_status_count/200': 3,
 'downloader/response_status_count/404': 1,
 'elapsed_time_seconds': 1045.340647,
 'finish_reason': 'timeout',
 'finish_time': datetime.datetime(2020, 3, 26, 3, 24, 24, 883439),
 'log_count/DEBUG': 4,
 'log_count/ERROR': 30,
 'log_count/INFO': 7,
 'request_depth_max': 3,
 'response_received_count': 4,
 'robotstxt/request_count': 1,
 'robotstxt/response_count': 1,
 'robotstxt/response_status_count/404': 1,
 'scheduler/dequeued': 3,
 'scheduler/dequeued/memory': 3,
 'scheduler/enqueued': 4,
 'scheduler/enqueued/memory': 4,
 'start_time': datetime.datetime(2020, 3, 26, 3, 6, 59, 542792)}
2020-03-26 11:24:24 [scrapy] INFO: Spider closed (timeout)
