2020-03-26 11:39:03 [scrapy] DEBUG: Retrying <GET http://quotes.toscrape.com/robots.txt> (failed 1 times): User timeout caused connection failure: Getting http://quotes.toscrape.com/robots.txt took longer than 180.0 seconds..
2020-03-26 11:40:33 [scrapy] DEBUG: Crawled (404) <GET http://quotes.toscrape.com/robots.txt> (referer: None)
2020-03-26 11:40:35 [scrapy] DEBUG: Crawled (200) <GET http://quotes.toscrape.com/> (referer: None)
2020-03-26 11:42:05 [scrapy] ERROR: Error processing {'author': 'Albert Einstein',
 'tags': ['change', 'deep-thoughts', 'thinking', 'world'],
 'text': '“The world as we have created it is a process of o...'}
Traceback (most recent call last):
  File "c:\users\w\anaconda3\lib\site-packages\twisted\internet\defer.py", line 654, in _runCallbacks
    current.result = callback(current.result, *args, **kw)
  File "c:\users\w\anaconda3\lib\site-packages\scrapy\utils\defer.py", line 154, in f
    return deferred_from_coro(coro_f(*coro_args, **coro_kwargs))
  File "E:\scrapy\ScrapyTutorial-master\tutorial\pipelines.py", line 36, in process_item
    self.db[name].insert(dict(item))
  File "c:\users\w\anaconda3\lib\site-packages\pymongo\collection.py", line 3182, in insert
    check_keys, manipulate, write_concern)
  File "c:\users\w\anaconda3\lib\site-packages\pymongo\collection.py", line 612, in _insert
    bypass_doc_val, session)
  File "c:\users\w\anaconda3\lib\site-packages\pymongo\collection.py", line 600, in _insert_one
    acknowledged, _insert_command, session)
  File "c:\users\w\anaconda3\lib\site-packages\pymongo\mongo_client.py", line 1491, in _retryable_write
    with self._tmp_session(session) as s:
  File "c:\users\w\anaconda3\lib\contextlib.py", line 59, in __enter__
    return next(self.gen)
  File "c:\users\w\anaconda3\lib\site-packages\pymongo\mongo_client.py", line 1820, in _tmp_session
    s = self._ensure_session(session)
  File "c:\users\w\anaconda3\lib\site-packages\pymongo\mongo_client.py", line 1807, in _ensure_session
    return self.__start_session(True, causal_consistency=False)
  File "c:\users\w\anaconda3\lib\site-packages\pymongo\mongo_client.py", line 1760, in __start_session
    server_session = self._get_server_session()
  File "c:\users\w\anaconda3\lib\site-packages\pymongo\mongo_client.py", line 1793, in _get_server_session
    return self._topology.get_server_session()
  File "c:\users\w\anaconda3\lib\site-packages\pymongo\topology.py", line 477, in get_server_session
    None)
  File "c:\users\w\anaconda3\lib\site-packages\pymongo\topology.py", line 205, in _select_servers_loop
    self._error_message(selector))
pymongo.errors.ServerSelectionTimeoutError: localhost:27017: [WinError 10061] 由于目标计算机积极拒绝，无法连接。
2020-03-26 11:44:06 [scrapy] ERROR: Error processing {'author': 'J.K. Rowling',
 'tags': ['abilities', 'choices'],
 'text': '“It is our choices, Harry, that show what we truly...'}
Traceback (most recent call last):
  File "c:\users\w\anaconda3\lib\site-packages\twisted\internet\defer.py", line 654, in _runCallbacks
    current.result = callback(current.result, *args, **kw)
  File "c:\users\w\anaconda3\lib\site-packages\scrapy\utils\defer.py", line 154, in f
    return deferred_from_coro(coro_f(*coro_args, **coro_kwargs))
  File "E:\scrapy\ScrapyTutorial-master\tutorial\pipelines.py", line 36, in process_item
    self.db[name].insert(dict(item))
  File "c:\users\w\anaconda3\lib\site-packages\pymongo\collection.py", line 3182, in insert
    check_keys, manipulate, write_concern)
  File "c:\users\w\anaconda3\lib\site-packages\pymongo\collection.py", line 612, in _insert
    bypass_doc_val, session)
  File "c:\users\w\anaconda3\lib\site-packages\pymongo\collection.py", line 600, in _insert_one
    acknowledged, _insert_command, session)
  File "c:\users\w\anaconda3\lib\site-packages\pymongo\mongo_client.py", line 1491, in _retryable_write
    with self._tmp_session(session) as s:
  File "c:\users\w\anaconda3\lib\contextlib.py", line 59, in __enter__
    return next(self.gen)
  File "c:\users\w\anaconda3\lib\site-packages\pymongo\mongo_client.py", line 1820, in _tmp_session
    s = self._ensure_session(session)
  File "c:\users\w\anaconda3\lib\site-packages\pymongo\mongo_client.py", line 1807, in _ensure_session
    return self.__start_session(True, causal_consistency=False)
  File "c:\users\w\anaconda3\lib\site-packages\pymongo\mongo_client.py", line 1760, in __start_session
    server_session = self._get_server_session()
  File "c:\users\w\anaconda3\lib\site-packages\pymongo\mongo_client.py", line 1793, in _get_server_session
    return self._topology.get_server_session()
  File "c:\users\w\anaconda3\lib\site-packages\pymongo\topology.py", line 477, in get_server_session
    None)
  File "c:\users\w\anaconda3\lib\site-packages\pymongo\topology.py", line 205, in _select_servers_loop
    self._error_message(selector))
pymongo.errors.ServerSelectionTimeoutError: localhost:27017: [WinError 10061] 由于目标计算机积极拒绝，无法连接。
2020-03-26 11:46:07 [scrapy] ERROR: Error processing {'author': 'Albert Einstein',
 'tags': ['inspirational', 'life', 'live', 'miracle', 'miracles'],
 'text': '“There are only two ways to live your life. One is...'}
Traceback (most recent call last):
  File "c:\users\w\anaconda3\lib\site-packages\twisted\internet\defer.py", line 654, in _runCallbacks
    current.result = callback(current.result, *args, **kw)
  File "c:\users\w\anaconda3\lib\site-packages\scrapy\utils\defer.py", line 154, in f
    return deferred_from_coro(coro_f(*coro_args, **coro_kwargs))
  File "E:\scrapy\ScrapyTutorial-master\tutorial\pipelines.py", line 36, in process_item
    self.db[name].insert(dict(item))
  File "c:\users\w\anaconda3\lib\site-packages\pymongo\collection.py", line 3182, in insert
    check_keys, manipulate, write_concern)
  File "c:\users\w\anaconda3\lib\site-packages\pymongo\collection.py", line 612, in _insert
    bypass_doc_val, session)
  File "c:\users\w\anaconda3\lib\site-packages\pymongo\collection.py", line 600, in _insert_one
    acknowledged, _insert_command, session)
  File "c:\users\w\anaconda3\lib\site-packages\pymongo\mongo_client.py", line 1491, in _retryable_write
    with self._tmp_session(session) as s:
  File "c:\users\w\anaconda3\lib\contextlib.py", line 59, in __enter__
    return next(self.gen)
  File "c:\users\w\anaconda3\lib\site-packages\pymongo\mongo_client.py", line 1820, in _tmp_session
    s = self._ensure_session(session)
  File "c:\users\w\anaconda3\lib\site-packages\pymongo\mongo_client.py", line 1807, in _ensure_session
    return self.__start_session(True, causal_consistency=False)
  File "c:\users\w\anaconda3\lib\site-packages\pymongo\mongo_client.py", line 1760, in __start_session
    server_session = self._get_server_session()
  File "c:\users\w\anaconda3\lib\site-packages\pymongo\mongo_client.py", line 1793, in _get_server_session
    return self._topology.get_server_session()
  File "c:\users\w\anaconda3\lib\site-packages\pymongo\topology.py", line 477, in get_server_session
    None)
  File "c:\users\w\anaconda3\lib\site-packages\pymongo\topology.py", line 205, in _select_servers_loop
    self._error_message(selector))
pymongo.errors.ServerSelectionTimeoutError: localhost:27017: [WinError 10061] 由于目标计算机积极拒绝，无法连接。
2020-03-26 11:48:08 [scrapy] ERROR: Error processing {'author': 'Jane Austen',
 'tags': ['aliteracy', 'books', 'classic', 'humor'],
 'text': '“The person, be it gentleman or lady, who has not...'}
Traceback (most recent call last):
  File "c:\users\w\anaconda3\lib\site-packages\twisted\internet\defer.py", line 654, in _runCallbacks
    current.result = callback(current.result, *args, **kw)
  File "c:\users\w\anaconda3\lib\site-packages\scrapy\utils\defer.py", line 154, in f
    return deferred_from_coro(coro_f(*coro_args, **coro_kwargs))
  File "E:\scrapy\ScrapyTutorial-master\tutorial\pipelines.py", line 36, in process_item
    self.db[name].insert(dict(item))
  File "c:\users\w\anaconda3\lib\site-packages\pymongo\collection.py", line 3182, in insert
    check_keys, manipulate, write_concern)
  File "c:\users\w\anaconda3\lib\site-packages\pymongo\collection.py", line 612, in _insert
    bypass_doc_val, session)
  File "c:\users\w\anaconda3\lib\site-packages\pymongo\collection.py", line 600, in _insert_one
    acknowledged, _insert_command, session)
  File "c:\users\w\anaconda3\lib\site-packages\pymongo\mongo_client.py", line 1491, in _retryable_write
    with self._tmp_session(session) as s:
  File "c:\users\w\anaconda3\lib\contextlib.py", line 59, in __enter__
    return next(self.gen)
  File "c:\users\w\anaconda3\lib\site-packages\pymongo\mongo_client.py", line 1820, in _tmp_session
    s = self._ensure_session(session)
  File "c:\users\w\anaconda3\lib\site-packages\pymongo\mongo_client.py", line 1807, in _ensure_session
    return self.__start_session(True, causal_consistency=False)
  File "c:\users\w\anaconda3\lib\site-packages\pymongo\mongo_client.py", line 1760, in __start_session
    server_session = self._get_server_session()
  File "c:\users\w\anaconda3\lib\site-packages\pymongo\mongo_client.py", line 1793, in _get_server_session
    return self._topology.get_server_session()
  File "c:\users\w\anaconda3\lib\site-packages\pymongo\topology.py", line 477, in get_server_session
    None)
  File "c:\users\w\anaconda3\lib\site-packages\pymongo\topology.py", line 205, in _select_servers_loop
    self._error_message(selector))
pymongo.errors.ServerSelectionTimeoutError: localhost:27017: [WinError 10061] 由于目标计算机积极拒绝，无法连接。
2020-03-26 11:50:09 [scrapy] ERROR: Error processing {'author': 'Marilyn Monroe',
 'tags': ['be-yourself', 'inspirational'],
 'text': "“Imperfection is beauty, madness is genius and it'..."}
Traceback (most recent call last):
  File "c:\users\w\anaconda3\lib\site-packages\twisted\internet\defer.py", line 654, in _runCallbacks
    current.result = callback(current.result, *args, **kw)
  File "c:\users\w\anaconda3\lib\site-packages\scrapy\utils\defer.py", line 154, in f
    return deferred_from_coro(coro_f(*coro_args, **coro_kwargs))
  File "E:\scrapy\ScrapyTutorial-master\tutorial\pipelines.py", line 36, in process_item
    self.db[name].insert(dict(item))
  File "c:\users\w\anaconda3\lib\site-packages\pymongo\collection.py", line 3182, in insert
    check_keys, manipulate, write_concern)
  File "c:\users\w\anaconda3\lib\site-packages\pymongo\collection.py", line 612, in _insert
    bypass_doc_val, session)
  File "c:\users\w\anaconda3\lib\site-packages\pymongo\collection.py", line 600, in _insert_one
    acknowledged, _insert_command, session)
  File "c:\users\w\anaconda3\lib\site-packages\pymongo\mongo_client.py", line 1491, in _retryable_write
    with self._tmp_session(session) as s:
  File "c:\users\w\anaconda3\lib\contextlib.py", line 59, in __enter__
    return next(self.gen)
  File "c:\users\w\anaconda3\lib\site-packages\pymongo\mongo_client.py", line 1820, in _tmp_session
    s = self._ensure_session(session)
  File "c:\users\w\anaconda3\lib\site-packages\pymongo\mongo_client.py", line 1807, in _ensure_session
    return self.__start_session(True, causal_consistency=False)
  File "c:\users\w\anaconda3\lib\site-packages\pymongo\mongo_client.py", line 1760, in __start_session
    server_session = self._get_server_session()
  File "c:\users\w\anaconda3\lib\site-packages\pymongo\mongo_client.py", line 1793, in _get_server_session
    return self._topology.get_server_session()
  File "c:\users\w\anaconda3\lib\site-packages\pymongo\topology.py", line 477, in get_server_session
    None)
  File "c:\users\w\anaconda3\lib\site-packages\pymongo\topology.py", line 205, in _select_servers_loop
    self._error_message(selector))
pymongo.errors.ServerSelectionTimeoutError: localhost:27017: [WinError 10061] 由于目标计算机积极拒绝，无法连接。
2020-03-26 11:52:10 [scrapy] ERROR: Error processing {'author': 'Albert Einstein',
 'tags': ['adulthood', 'success', 'value'],
 'text': '“Try not to become a man of success. Rather become...'}
Traceback (most recent call last):
  File "c:\users\w\anaconda3\lib\site-packages\twisted\internet\defer.py", line 654, in _runCallbacks
    current.result = callback(current.result, *args, **kw)
  File "c:\users\w\anaconda3\lib\site-packages\scrapy\utils\defer.py", line 154, in f
    return deferred_from_coro(coro_f(*coro_args, **coro_kwargs))
  File "E:\scrapy\ScrapyTutorial-master\tutorial\pipelines.py", line 36, in process_item
    self.db[name].insert(dict(item))
  File "c:\users\w\anaconda3\lib\site-packages\pymongo\collection.py", line 3182, in insert
    check_keys, manipulate, write_concern)
  File "c:\users\w\anaconda3\lib\site-packages\pymongo\collection.py", line 612, in _insert
    bypass_doc_val, session)
  File "c:\users\w\anaconda3\lib\site-packages\pymongo\collection.py", line 600, in _insert_one
    acknowledged, _insert_command, session)
  File "c:\users\w\anaconda3\lib\site-packages\pymongo\mongo_client.py", line 1491, in _retryable_write
    with self._tmp_session(session) as s:
  File "c:\users\w\anaconda3\lib\contextlib.py", line 59, in __enter__
    return next(self.gen)
  File "c:\users\w\anaconda3\lib\site-packages\pymongo\mongo_client.py", line 1820, in _tmp_session
    s = self._ensure_session(session)
  File "c:\users\w\anaconda3\lib\site-packages\pymongo\mongo_client.py", line 1807, in _ensure_session
    return self.__start_session(True, causal_consistency=False)
  File "c:\users\w\anaconda3\lib\site-packages\pymongo\mongo_client.py", line 1760, in __start_session
    server_session = self._get_server_session()
  File "c:\users\w\anaconda3\lib\site-packages\pymongo\mongo_client.py", line 1793, in _get_server_session
    return self._topology.get_server_session()
  File "c:\users\w\anaconda3\lib\site-packages\pymongo\topology.py", line 477, in get_server_session
    None)
  File "c:\users\w\anaconda3\lib\site-packages\pymongo\topology.py", line 205, in _select_servers_loop
    self._error_message(selector))
pymongo.errors.ServerSelectionTimeoutError: localhost:27017: [WinError 10061] 由于目标计算机积极拒绝，无法连接。
2020-03-26 11:54:11 [scrapy] ERROR: Error processing {'author': 'André Gide',
 'tags': ['life', 'love'],
 'text': '“It is better to be hated for what you are than to...'}
Traceback (most recent call last):
  File "c:\users\w\anaconda3\lib\site-packages\twisted\internet\defer.py", line 654, in _runCallbacks
    current.result = callback(current.result, *args, **kw)
  File "c:\users\w\anaconda3\lib\site-packages\scrapy\utils\defer.py", line 154, in f
    return deferred_from_coro(coro_f(*coro_args, **coro_kwargs))
  File "E:\scrapy\ScrapyTutorial-master\tutorial\pipelines.py", line 36, in process_item
    self.db[name].insert(dict(item))
  File "c:\users\w\anaconda3\lib\site-packages\pymongo\collection.py", line 3182, in insert
    check_keys, manipulate, write_concern)
  File "c:\users\w\anaconda3\lib\site-packages\pymongo\collection.py", line 612, in _insert
    bypass_doc_val, session)
  File "c:\users\w\anaconda3\lib\site-packages\pymongo\collection.py", line 600, in _insert_one
    acknowledged, _insert_command, session)
  File "c:\users\w\anaconda3\lib\site-packages\pymongo\mongo_client.py", line 1491, in _retryable_write
    with self._tmp_session(session) as s:
  File "c:\users\w\anaconda3\lib\contextlib.py", line 59, in __enter__
    return next(self.gen)
  File "c:\users\w\anaconda3\lib\site-packages\pymongo\mongo_client.py", line 1820, in _tmp_session
    s = self._ensure_session(session)
  File "c:\users\w\anaconda3\lib\site-packages\pymongo\mongo_client.py", line 1807, in _ensure_session
    return self.__start_session(True, causal_consistency=False)
  File "c:\users\w\anaconda3\lib\site-packages\pymongo\mongo_client.py", line 1760, in __start_session
    server_session = self._get_server_session()
  File "c:\users\w\anaconda3\lib\site-packages\pymongo\mongo_client.py", line 1793, in _get_server_session
    return self._topology.get_server_session()
  File "c:\users\w\anaconda3\lib\site-packages\pymongo\topology.py", line 477, in get_server_session
    None)
  File "c:\users\w\anaconda3\lib\site-packages\pymongo\topology.py", line 205, in _select_servers_loop
    self._error_message(selector))
pymongo.errors.ServerSelectionTimeoutError: localhost:27017: [WinError 10061] 由于目标计算机积极拒绝，无法连接。
2020-03-26 11:56:13 [scrapy] ERROR: Error processing {'author': 'Thomas A. Edison',
 'tags': ['edison', 'failure', 'inspirational', 'paraphrased'],
 'text': "“I have not failed. I've just found 10,000 ways th..."}
Traceback (most recent call last):
  File "c:\users\w\anaconda3\lib\site-packages\twisted\internet\defer.py", line 654, in _runCallbacks
    current.result = callback(current.result, *args, **kw)
  File "c:\users\w\anaconda3\lib\site-packages\scrapy\utils\defer.py", line 154, in f
    return deferred_from_coro(coro_f(*coro_args, **coro_kwargs))
  File "E:\scrapy\ScrapyTutorial-master\tutorial\pipelines.py", line 36, in process_item
    self.db[name].insert(dict(item))
  File "c:\users\w\anaconda3\lib\site-packages\pymongo\collection.py", line 3182, in insert
    check_keys, manipulate, write_concern)
  File "c:\users\w\anaconda3\lib\site-packages\pymongo\collection.py", line 612, in _insert
    bypass_doc_val, session)
  File "c:\users\w\anaconda3\lib\site-packages\pymongo\collection.py", line 600, in _insert_one
    acknowledged, _insert_command, session)
  File "c:\users\w\anaconda3\lib\site-packages\pymongo\mongo_client.py", line 1491, in _retryable_write
    with self._tmp_session(session) as s:
  File "c:\users\w\anaconda3\lib\contextlib.py", line 59, in __enter__
    return next(self.gen)
  File "c:\users\w\anaconda3\lib\site-packages\pymongo\mongo_client.py", line 1820, in _tmp_session
    s = self._ensure_session(session)
  File "c:\users\w\anaconda3\lib\site-packages\pymongo\mongo_client.py", line 1807, in _ensure_session
    return self.__start_session(True, causal_consistency=False)
  File "c:\users\w\anaconda3\lib\site-packages\pymongo\mongo_client.py", line 1760, in __start_session
    server_session = self._get_server_session()
  File "c:\users\w\anaconda3\lib\site-packages\pymongo\mongo_client.py", line 1793, in _get_server_session
    return self._topology.get_server_session()
  File "c:\users\w\anaconda3\lib\site-packages\pymongo\topology.py", line 477, in get_server_session
    None)
  File "c:\users\w\anaconda3\lib\site-packages\pymongo\topology.py", line 205, in _select_servers_loop
    self._error_message(selector))
pymongo.errors.ServerSelectionTimeoutError: localhost:27017: [WinError 10061] 由于目标计算机积极拒绝，无法连接。
2020-03-26 12:14:43 [scrapy] ERROR: Error processing {'author': 'Eleanor Roosevelt',
 'tags': ['misattributed-eleanor-roosevelt'],
 'text': '“A woman is like a tea bag; you never know how str...'}
Traceback (most recent call last):
  File "c:\users\w\anaconda3\lib\site-packages\twisted\internet\defer.py", line 654, in _runCallbacks
    current.result = callback(current.result, *args, **kw)
  File "c:\users\w\anaconda3\lib\site-packages\scrapy\utils\defer.py", line 154, in f
    return deferred_from_coro(coro_f(*coro_args, **coro_kwargs))
  File "E:\scrapy\ScrapyTutorial-master\tutorial\pipelines.py", line 36, in process_item
    self.db[name].insert(dict(item))
  File "c:\users\w\anaconda3\lib\site-packages\pymongo\collection.py", line 3182, in insert
    check_keys, manipulate, write_concern)
  File "c:\users\w\anaconda3\lib\site-packages\pymongo\collection.py", line 612, in _insert
    bypass_doc_val, session)
  File "c:\users\w\anaconda3\lib\site-packages\pymongo\collection.py", line 600, in _insert_one
    acknowledged, _insert_command, session)
  File "c:\users\w\anaconda3\lib\site-packages\pymongo\mongo_client.py", line 1491, in _retryable_write
    with self._tmp_session(session) as s:
  File "c:\users\w\anaconda3\lib\contextlib.py", line 59, in __enter__
    return next(self.gen)
  File "c:\users\w\anaconda3\lib\site-packages\pymongo\mongo_client.py", line 1820, in _tmp_session
    s = self._ensure_session(session)
  File "c:\users\w\anaconda3\lib\site-packages\pymongo\mongo_client.py", line 1807, in _ensure_session
    return self.__start_session(True, causal_consistency=False)
  File "c:\users\w\anaconda3\lib\site-packages\pymongo\mongo_client.py", line 1760, in __start_session
    server_session = self._get_server_session()
  File "c:\users\w\anaconda3\lib\site-packages\pymongo\mongo_client.py", line 1793, in _get_server_session
    return self._topology.get_server_session()
  File "c:\users\w\anaconda3\lib\site-packages\pymongo\topology.py", line 477, in get_server_session
    None)
  File "c:\users\w\anaconda3\lib\site-packages\pymongo\topology.py", line 205, in _select_servers_loop
    self._error_message(selector))
pymongo.errors.ServerSelectionTimeoutError: localhost:27017: [WinError 10061] 由于目标计算机积极拒绝，无法连接。
2020-03-26 12:16:14 [scrapy] ERROR: Error processing {'author': 'Steve Martin',
 'tags': ['humor', 'obvious', 'simile'],
 'text': '“A day without sunshine is like, you know, night.”'}
Traceback (most recent call last):
  File "c:\users\w\anaconda3\lib\site-packages\twisted\internet\defer.py", line 654, in _runCallbacks
    current.result = callback(current.result, *args, **kw)
  File "c:\users\w\anaconda3\lib\site-packages\scrapy\utils\defer.py", line 154, in f
    return deferred_from_coro(coro_f(*coro_args, **coro_kwargs))
  File "E:\scrapy\ScrapyTutorial-master\tutorial\pipelines.py", line 36, in process_item
    self.db[name].insert(dict(item))
  File "c:\users\w\anaconda3\lib\site-packages\pymongo\collection.py", line 3182, in insert
    check_keys, manipulate, write_concern)
  File "c:\users\w\anaconda3\lib\site-packages\pymongo\collection.py", line 612, in _insert
    bypass_doc_val, session)
  File "c:\users\w\anaconda3\lib\site-packages\pymongo\collection.py", line 600, in _insert_one
    acknowledged, _insert_command, session)
  File "c:\users\w\anaconda3\lib\site-packages\pymongo\mongo_client.py", line 1491, in _retryable_write
    with self._tmp_session(session) as s:
  File "c:\users\w\anaconda3\lib\contextlib.py", line 59, in __enter__
    return next(self.gen)
  File "c:\users\w\anaconda3\lib\site-packages\pymongo\mongo_client.py", line 1820, in _tmp_session
    s = self._ensure_session(session)
  File "c:\users\w\anaconda3\lib\site-packages\pymongo\mongo_client.py", line 1807, in _ensure_session
    return self.__start_session(True, causal_consistency=False)
  File "c:\users\w\anaconda3\lib\site-packages\pymongo\mongo_client.py", line 1760, in __start_session
    server_session = self._get_server_session()
  File "c:\users\w\anaconda3\lib\site-packages\pymongo\mongo_client.py", line 1793, in _get_server_session
    return self._topology.get_server_session()
  File "c:\users\w\anaconda3\lib\site-packages\pymongo\topology.py", line 477, in get_server_session
    None)
  File "c:\users\w\anaconda3\lib\site-packages\pymongo\topology.py", line 205, in _select_servers_loop
    self._error_message(selector))
pymongo.errors.ServerSelectionTimeoutError: localhost:27017: [WinError 10061] 由于目标计算机积极拒绝，无法连接。
2020-03-26 12:17:14 [scrapy] INFO: Closing spider (timeout)
2020-03-26 12:17:14 [scrapy] INFO: Dumping Scrapy stats:
{'downloader/exception_count': 1,
 'downloader/exception_type_count/twisted.internet.error.TimeoutError': 1,
 'downloader/request_bytes': 689,
 'downloader/request_count': 3,
 'downloader/request_method_count/GET': 3,
 'downloader/response_bytes': 2719,
 'downloader/response_count': 2,
 'downloader/response_status_count/200': 1,
 'downloader/response_status_count/404': 1,
 'elapsed_time_seconds': 2624.407425,
 'finish_reason': 'timeout',
 'finish_time': datetime.datetime(2020, 3, 26, 4, 17, 14, 702193),
 'log_count/DEBUG': 9,
 'log_count/ERROR': 54,
 'log_count/INFO': 16,
 'request_depth_max': 1,
 'response_received_count': 2,
 'retry/count': 1,
 'retry/reason_count/twisted.internet.error.TimeoutError': 1,
 'robotstxt/request_count': 1,
 'robotstxt/response_count': 1,
 'robotstxt/response_status_count/404': 1,
 'scheduler/dequeued': 1,
 'scheduler/dequeued/memory': 1,
 'scheduler/enqueued': 2,
 'scheduler/enqueued/memory': 2,
 'start_time': datetime.datetime(2020, 3, 26, 3, 33, 30, 294768)}
2020-03-26 12:17:14 [scrapy] INFO: Spider closed (timeout)
