2020-03-26 11:29:57 [scrapy] DEBUG: Crawled (404) <GET http://quotes.toscrape.com/robots.txt> (referer: None)
2020-03-26 11:29:57 [scrapy] DEBUG: Crawled (200) <GET http://quotes.toscrape.com/> (referer: None)
2020-03-26 11:31:27 [scrapy] ERROR: Error processing {'author': 'Albert Einstein',
 'tags': ['change', 'deep-thoughts', 'thinking', 'world'],
 'text': '“The world as we have created it is a process of o...'}
Traceback (most recent call last):
  File "c:\users\w\anaconda3\lib\site-packages\twisted\internet\defer.py", line 654, in _runCallbacks
    current.result = callback(current.result, *args, **kw)
  File "c:\users\w\anaconda3\lib\site-packages\scrapy\utils\defer.py", line 154, in f
    return deferred_from_coro(coro_f(*coro_args, **coro_kwargs))
  File "E:\scrapy\ScrapyTutorial-master\tutorial\pipelines.py", line 36, in process_item
    self.db[name].insert(dict(item))
  File "c:\users\w\anaconda3\lib\site-packages\pymongo\collection.py", line 3182, in insert
    check_keys, manipulate, write_concern)
  File "c:\users\w\anaconda3\lib\site-packages\pymongo\collection.py", line 612, in _insert
    bypass_doc_val, session)
  File "c:\users\w\anaconda3\lib\site-packages\pymongo\collection.py", line 600, in _insert_one
    acknowledged, _insert_command, session)
  File "c:\users\w\anaconda3\lib\site-packages\pymongo\mongo_client.py", line 1491, in _retryable_write
    with self._tmp_session(session) as s:
  File "c:\users\w\anaconda3\lib\contextlib.py", line 59, in __enter__
    return next(self.gen)
  File "c:\users\w\anaconda3\lib\site-packages\pymongo\mongo_client.py", line 1820, in _tmp_session
    s = self._ensure_session(session)
  File "c:\users\w\anaconda3\lib\site-packages\pymongo\mongo_client.py", line 1807, in _ensure_session
    return self.__start_session(True, causal_consistency=False)
  File "c:\users\w\anaconda3\lib\site-packages\pymongo\mongo_client.py", line 1760, in __start_session
    server_session = self._get_server_session()
  File "c:\users\w\anaconda3\lib\site-packages\pymongo\mongo_client.py", line 1793, in _get_server_session
    return self._topology.get_server_session()
  File "c:\users\w\anaconda3\lib\site-packages\pymongo\topology.py", line 477, in get_server_session
    None)
  File "c:\users\w\anaconda3\lib\site-packages\pymongo\topology.py", line 205, in _select_servers_loop
    self._error_message(selector))
pymongo.errors.ServerSelectionTimeoutError: localhost:27017: [WinError 10061] 由于目标计算机积极拒绝，无法连接。
2020-03-26 11:32:28 [scrapy] ERROR: Error processing {'author': 'J.K. Rowling',
 'tags': ['abilities', 'choices'],
 'text': '“It is our choices, Harry, that show what we truly...'}
Traceback (most recent call last):
  File "c:\users\w\anaconda3\lib\site-packages\twisted\internet\defer.py", line 654, in _runCallbacks
    current.result = callback(current.result, *args, **kw)
  File "c:\users\w\anaconda3\lib\site-packages\scrapy\utils\defer.py", line 154, in f
    return deferred_from_coro(coro_f(*coro_args, **coro_kwargs))
  File "E:\scrapy\ScrapyTutorial-master\tutorial\pipelines.py", line 36, in process_item
    self.db[name].insert(dict(item))
  File "c:\users\w\anaconda3\lib\site-packages\pymongo\collection.py", line 3182, in insert
    check_keys, manipulate, write_concern)
  File "c:\users\w\anaconda3\lib\site-packages\pymongo\collection.py", line 612, in _insert
    bypass_doc_val, session)
  File "c:\users\w\anaconda3\lib\site-packages\pymongo\collection.py", line 600, in _insert_one
    acknowledged, _insert_command, session)
  File "c:\users\w\anaconda3\lib\site-packages\pymongo\mongo_client.py", line 1491, in _retryable_write
    with self._tmp_session(session) as s:
  File "c:\users\w\anaconda3\lib\contextlib.py", line 59, in __enter__
    return next(self.gen)
  File "c:\users\w\anaconda3\lib\site-packages\pymongo\mongo_client.py", line 1820, in _tmp_session
    s = self._ensure_session(session)
  File "c:\users\w\anaconda3\lib\site-packages\pymongo\mongo_client.py", line 1807, in _ensure_session
    return self.__start_session(True, causal_consistency=False)
  File "c:\users\w\anaconda3\lib\site-packages\pymongo\mongo_client.py", line 1760, in __start_session
    server_session = self._get_server_session()
  File "c:\users\w\anaconda3\lib\site-packages\pymongo\mongo_client.py", line 1793, in _get_server_session
    return self._topology.get_server_session()
  File "c:\users\w\anaconda3\lib\site-packages\pymongo\topology.py", line 477, in get_server_session
    None)
  File "c:\users\w\anaconda3\lib\site-packages\pymongo\topology.py", line 205, in _select_servers_loop
    self._error_message(selector))
pymongo.errors.ServerSelectionTimeoutError: localhost:27017: [WinError 10061] 由于目标计算机积极拒绝，无法连接。
2020-03-26 11:34:00 [scrapy] ERROR: Error processing {'author': 'Albert Einstein',
 'tags': ['inspirational', 'life', 'live', 'miracle', 'miracles'],
 'text': '“There are only two ways to live your life. One is...'}
Traceback (most recent call last):
  File "c:\users\w\anaconda3\lib\site-packages\twisted\internet\defer.py", line 654, in _runCallbacks
    current.result = callback(current.result, *args, **kw)
  File "c:\users\w\anaconda3\lib\site-packages\scrapy\utils\defer.py", line 154, in f
    return deferred_from_coro(coro_f(*coro_args, **coro_kwargs))
  File "E:\scrapy\ScrapyTutorial-master\tutorial\pipelines.py", line 36, in process_item
    self.db[name].insert(dict(item))
  File "c:\users\w\anaconda3\lib\site-packages\pymongo\collection.py", line 3182, in insert
    check_keys, manipulate, write_concern)
  File "c:\users\w\anaconda3\lib\site-packages\pymongo\collection.py", line 612, in _insert
    bypass_doc_val, session)
  File "c:\users\w\anaconda3\lib\site-packages\pymongo\collection.py", line 600, in _insert_one
    acknowledged, _insert_command, session)
  File "c:\users\w\anaconda3\lib\site-packages\pymongo\mongo_client.py", line 1491, in _retryable_write
    with self._tmp_session(session) as s:
  File "c:\users\w\anaconda3\lib\contextlib.py", line 59, in __enter__
    return next(self.gen)
  File "c:\users\w\anaconda3\lib\site-packages\pymongo\mongo_client.py", line 1820, in _tmp_session
    s = self._ensure_session(session)
  File "c:\users\w\anaconda3\lib\site-packages\pymongo\mongo_client.py", line 1807, in _ensure_session
    return self.__start_session(True, causal_consistency=False)
  File "c:\users\w\anaconda3\lib\site-packages\pymongo\mongo_client.py", line 1760, in __start_session
    server_session = self._get_server_session()
  File "c:\users\w\anaconda3\lib\site-packages\pymongo\mongo_client.py", line 1793, in _get_server_session
    return self._topology.get_server_session()
  File "c:\users\w\anaconda3\lib\site-packages\pymongo\topology.py", line 477, in get_server_session
    None)
  File "c:\users\w\anaconda3\lib\site-packages\pymongo\topology.py", line 205, in _select_servers_loop
    self._error_message(selector))
pymongo.errors.ServerSelectionTimeoutError: localhost:27017: [WinError 10061] 由于目标计算机积极拒绝，无法连接。
2020-03-26 11:35:01 [scrapy] ERROR: Error processing {'author': 'Jane Austen',
 'tags': ['aliteracy', 'books', 'classic', 'humor'],
 'text': '“The person, be it gentleman or lady, who has not...'}
Traceback (most recent call last):
  File "c:\users\w\anaconda3\lib\site-packages\twisted\internet\defer.py", line 654, in _runCallbacks
    current.result = callback(current.result, *args, **kw)
  File "c:\users\w\anaconda3\lib\site-packages\scrapy\utils\defer.py", line 154, in f
    return deferred_from_coro(coro_f(*coro_args, **coro_kwargs))
  File "E:\scrapy\ScrapyTutorial-master\tutorial\pipelines.py", line 36, in process_item
    self.db[name].insert(dict(item))
  File "c:\users\w\anaconda3\lib\site-packages\pymongo\collection.py", line 3182, in insert
    check_keys, manipulate, write_concern)
  File "c:\users\w\anaconda3\lib\site-packages\pymongo\collection.py", line 612, in _insert
    bypass_doc_val, session)
  File "c:\users\w\anaconda3\lib\site-packages\pymongo\collection.py", line 600, in _insert_one
    acknowledged, _insert_command, session)
  File "c:\users\w\anaconda3\lib\site-packages\pymongo\mongo_client.py", line 1491, in _retryable_write
    with self._tmp_session(session) as s:
  File "c:\users\w\anaconda3\lib\contextlib.py", line 59, in __enter__
    return next(self.gen)
  File "c:\users\w\anaconda3\lib\site-packages\pymongo\mongo_client.py", line 1820, in _tmp_session
    s = self._ensure_session(session)
  File "c:\users\w\anaconda3\lib\site-packages\pymongo\mongo_client.py", line 1807, in _ensure_session
    return self.__start_session(True, causal_consistency=False)
  File "c:\users\w\anaconda3\lib\site-packages\pymongo\mongo_client.py", line 1760, in __start_session
    server_session = self._get_server_session()
  File "c:\users\w\anaconda3\lib\site-packages\pymongo\mongo_client.py", line 1793, in _get_server_session
    return self._topology.get_server_session()
  File "c:\users\w\anaconda3\lib\site-packages\pymongo\topology.py", line 477, in get_server_session
    None)
  File "c:\users\w\anaconda3\lib\site-packages\pymongo\topology.py", line 205, in _select_servers_loop
    self._error_message(selector))
pymongo.errors.ServerSelectionTimeoutError: localhost:27017: [WinError 10061] 由于目标计算机积极拒绝，无法连接。
2020-03-26 11:36:01 [scrapy] ERROR: Error processing {'author': 'Marilyn Monroe',
 'tags': ['be-yourself', 'inspirational'],
 'text': "“Imperfection is beauty, madness is genius and it'..."}
Traceback (most recent call last):
  File "c:\users\w\anaconda3\lib\site-packages\twisted\internet\defer.py", line 654, in _runCallbacks
    current.result = callback(current.result, *args, **kw)
  File "c:\users\w\anaconda3\lib\site-packages\scrapy\utils\defer.py", line 154, in f
    return deferred_from_coro(coro_f(*coro_args, **coro_kwargs))
  File "E:\scrapy\ScrapyTutorial-master\tutorial\pipelines.py", line 36, in process_item
    self.db[name].insert(dict(item))
  File "c:\users\w\anaconda3\lib\site-packages\pymongo\collection.py", line 3182, in insert
    check_keys, manipulate, write_concern)
  File "c:\users\w\anaconda3\lib\site-packages\pymongo\collection.py", line 612, in _insert
    bypass_doc_val, session)
  File "c:\users\w\anaconda3\lib\site-packages\pymongo\collection.py", line 600, in _insert_one
    acknowledged, _insert_command, session)
  File "c:\users\w\anaconda3\lib\site-packages\pymongo\mongo_client.py", line 1491, in _retryable_write
    with self._tmp_session(session) as s:
  File "c:\users\w\anaconda3\lib\contextlib.py", line 59, in __enter__
    return next(self.gen)
  File "c:\users\w\anaconda3\lib\site-packages\pymongo\mongo_client.py", line 1820, in _tmp_session
    s = self._ensure_session(session)
  File "c:\users\w\anaconda3\lib\site-packages\pymongo\mongo_client.py", line 1807, in _ensure_session
    return self.__start_session(True, causal_consistency=False)
  File "c:\users\w\anaconda3\lib\site-packages\pymongo\mongo_client.py", line 1760, in __start_session
    server_session = self._get_server_session()
  File "c:\users\w\anaconda3\lib\site-packages\pymongo\mongo_client.py", line 1793, in _get_server_session
    return self._topology.get_server_session()
  File "c:\users\w\anaconda3\lib\site-packages\pymongo\topology.py", line 477, in get_server_session
    None)
  File "c:\users\w\anaconda3\lib\site-packages\pymongo\topology.py", line 205, in _select_servers_loop
    self._error_message(selector))
pymongo.errors.ServerSelectionTimeoutError: localhost:27017: [WinError 10061] 由于目标计算机积极拒绝，无法连接。
2020-03-26 11:37:02 [scrapy] ERROR: Error processing {'author': 'Albert Einstein',
 'tags': ['adulthood', 'success', 'value'],
 'text': '“Try not to become a man of success. Rather become...'}
Traceback (most recent call last):
  File "c:\users\w\anaconda3\lib\site-packages\twisted\internet\defer.py", line 654, in _runCallbacks
    current.result = callback(current.result, *args, **kw)
  File "c:\users\w\anaconda3\lib\site-packages\scrapy\utils\defer.py", line 154, in f
    return deferred_from_coro(coro_f(*coro_args, **coro_kwargs))
  File "E:\scrapy\ScrapyTutorial-master\tutorial\pipelines.py", line 36, in process_item
    self.db[name].insert(dict(item))
  File "c:\users\w\anaconda3\lib\site-packages\pymongo\collection.py", line 3182, in insert
    check_keys, manipulate, write_concern)
  File "c:\users\w\anaconda3\lib\site-packages\pymongo\collection.py", line 612, in _insert
    bypass_doc_val, session)
  File "c:\users\w\anaconda3\lib\site-packages\pymongo\collection.py", line 600, in _insert_one
    acknowledged, _insert_command, session)
  File "c:\users\w\anaconda3\lib\site-packages\pymongo\mongo_client.py", line 1491, in _retryable_write
    with self._tmp_session(session) as s:
  File "c:\users\w\anaconda3\lib\contextlib.py", line 59, in __enter__
    return next(self.gen)
  File "c:\users\w\anaconda3\lib\site-packages\pymongo\mongo_client.py", line 1820, in _tmp_session
    s = self._ensure_session(session)
  File "c:\users\w\anaconda3\lib\site-packages\pymongo\mongo_client.py", line 1807, in _ensure_session
    return self.__start_session(True, causal_consistency=False)
  File "c:\users\w\anaconda3\lib\site-packages\pymongo\mongo_client.py", line 1760, in __start_session
    server_session = self._get_server_session()
  File "c:\users\w\anaconda3\lib\site-packages\pymongo\mongo_client.py", line 1793, in _get_server_session
    return self._topology.get_server_session()
  File "c:\users\w\anaconda3\lib\site-packages\pymongo\topology.py", line 477, in get_server_session
    None)
  File "c:\users\w\anaconda3\lib\site-packages\pymongo\topology.py", line 205, in _select_servers_loop
    self._error_message(selector))
pymongo.errors.ServerSelectionTimeoutError: localhost:27017: [WinError 10061] 由于目标计算机积极拒绝，无法连接。
2020-03-26 11:38:02 [scrapy] ERROR: Error processing {'author': 'André Gide',
 'tags': ['life', 'love'],
 'text': '“It is better to be hated for what you are than to...'}
Traceback (most recent call last):
  File "c:\users\w\anaconda3\lib\site-packages\twisted\internet\defer.py", line 654, in _runCallbacks
    current.result = callback(current.result, *args, **kw)
  File "c:\users\w\anaconda3\lib\site-packages\scrapy\utils\defer.py", line 154, in f
    return deferred_from_coro(coro_f(*coro_args, **coro_kwargs))
  File "E:\scrapy\ScrapyTutorial-master\tutorial\pipelines.py", line 36, in process_item
    self.db[name].insert(dict(item))
  File "c:\users\w\anaconda3\lib\site-packages\pymongo\collection.py", line 3182, in insert
    check_keys, manipulate, write_concern)
  File "c:\users\w\anaconda3\lib\site-packages\pymongo\collection.py", line 612, in _insert
    bypass_doc_val, session)
  File "c:\users\w\anaconda3\lib\site-packages\pymongo\collection.py", line 600, in _insert_one
    acknowledged, _insert_command, session)
  File "c:\users\w\anaconda3\lib\site-packages\pymongo\mongo_client.py", line 1491, in _retryable_write
    with self._tmp_session(session) as s:
  File "c:\users\w\anaconda3\lib\contextlib.py", line 59, in __enter__
    return next(self.gen)
  File "c:\users\w\anaconda3\lib\site-packages\pymongo\mongo_client.py", line 1820, in _tmp_session
    s = self._ensure_session(session)
  File "c:\users\w\anaconda3\lib\site-packages\pymongo\mongo_client.py", line 1807, in _ensure_session
    return self.__start_session(True, causal_consistency=False)
  File "c:\users\w\anaconda3\lib\site-packages\pymongo\mongo_client.py", line 1760, in __start_session
    server_session = self._get_server_session()
  File "c:\users\w\anaconda3\lib\site-packages\pymongo\mongo_client.py", line 1793, in _get_server_session
    return self._topology.get_server_session()
  File "c:\users\w\anaconda3\lib\site-packages\pymongo\topology.py", line 477, in get_server_session
    None)
  File "c:\users\w\anaconda3\lib\site-packages\pymongo\topology.py", line 205, in _select_servers_loop
    self._error_message(selector))
pymongo.errors.ServerSelectionTimeoutError: localhost:27017: [WinError 10061] 由于目标计算机积极拒绝，无法连接。
2020-03-26 11:39:03 [scrapy] ERROR: Error processing {'author': 'Thomas A. Edison',
 'tags': ['edison', 'failure', 'inspirational', 'paraphrased'],
 'text': "“I have not failed. I've just found 10,000 ways th..."}
Traceback (most recent call last):
  File "c:\users\w\anaconda3\lib\site-packages\twisted\internet\defer.py", line 654, in _runCallbacks
    current.result = callback(current.result, *args, **kw)
  File "c:\users\w\anaconda3\lib\site-packages\scrapy\utils\defer.py", line 154, in f
    return deferred_from_coro(coro_f(*coro_args, **coro_kwargs))
  File "E:\scrapy\ScrapyTutorial-master\tutorial\pipelines.py", line 36, in process_item
    self.db[name].insert(dict(item))
  File "c:\users\w\anaconda3\lib\site-packages\pymongo\collection.py", line 3182, in insert
    check_keys, manipulate, write_concern)
  File "c:\users\w\anaconda3\lib\site-packages\pymongo\collection.py", line 612, in _insert
    bypass_doc_val, session)
  File "c:\users\w\anaconda3\lib\site-packages\pymongo\collection.py", line 600, in _insert_one
    acknowledged, _insert_command, session)
  File "c:\users\w\anaconda3\lib\site-packages\pymongo\mongo_client.py", line 1491, in _retryable_write
    with self._tmp_session(session) as s:
  File "c:\users\w\anaconda3\lib\contextlib.py", line 59, in __enter__
    return next(self.gen)
  File "c:\users\w\anaconda3\lib\site-packages\pymongo\mongo_client.py", line 1820, in _tmp_session
    s = self._ensure_session(session)
  File "c:\users\w\anaconda3\lib\site-packages\pymongo\mongo_client.py", line 1807, in _ensure_session
    return self.__start_session(True, causal_consistency=False)
  File "c:\users\w\anaconda3\lib\site-packages\pymongo\mongo_client.py", line 1760, in __start_session
    server_session = self._get_server_session()
  File "c:\users\w\anaconda3\lib\site-packages\pymongo\mongo_client.py", line 1793, in _get_server_session
    return self._topology.get_server_session()
  File "c:\users\w\anaconda3\lib\site-packages\pymongo\topology.py", line 477, in get_server_session
    None)
  File "c:\users\w\anaconda3\lib\site-packages\pymongo\topology.py", line 205, in _select_servers_loop
    self._error_message(selector))
pymongo.errors.ServerSelectionTimeoutError: localhost:27017: [WinError 10061] 由于目标计算机积极拒绝，无法连接。
2020-03-26 11:40:03 [scrapy] ERROR: Error processing {'author': 'Eleanor Roosevelt',
 'tags': ['misattributed-eleanor-roosevelt'],
 'text': '“A woman is like a tea bag; you never know how str...'}
Traceback (most recent call last):
  File "c:\users\w\anaconda3\lib\site-packages\twisted\internet\defer.py", line 654, in _runCallbacks
    current.result = callback(current.result, *args, **kw)
  File "c:\users\w\anaconda3\lib\site-packages\scrapy\utils\defer.py", line 154, in f
    return deferred_from_coro(coro_f(*coro_args, **coro_kwargs))
  File "E:\scrapy\ScrapyTutorial-master\tutorial\pipelines.py", line 36, in process_item
    self.db[name].insert(dict(item))
  File "c:\users\w\anaconda3\lib\site-packages\pymongo\collection.py", line 3182, in insert
    check_keys, manipulate, write_concern)
  File "c:\users\w\anaconda3\lib\site-packages\pymongo\collection.py", line 612, in _insert
    bypass_doc_val, session)
  File "c:\users\w\anaconda3\lib\site-packages\pymongo\collection.py", line 600, in _insert_one
    acknowledged, _insert_command, session)
  File "c:\users\w\anaconda3\lib\site-packages\pymongo\mongo_client.py", line 1491, in _retryable_write
    with self._tmp_session(session) as s:
  File "c:\users\w\anaconda3\lib\contextlib.py", line 59, in __enter__
    return next(self.gen)
  File "c:\users\w\anaconda3\lib\site-packages\pymongo\mongo_client.py", line 1820, in _tmp_session
    s = self._ensure_session(session)
  File "c:\users\w\anaconda3\lib\site-packages\pymongo\mongo_client.py", line 1807, in _ensure_session
    return self.__start_session(True, causal_consistency=False)
  File "c:\users\w\anaconda3\lib\site-packages\pymongo\mongo_client.py", line 1760, in __start_session
    server_session = self._get_server_session()
  File "c:\users\w\anaconda3\lib\site-packages\pymongo\mongo_client.py", line 1793, in _get_server_session
    return self._topology.get_server_session()
  File "c:\users\w\anaconda3\lib\site-packages\pymongo\topology.py", line 477, in get_server_session
    None)
  File "c:\users\w\anaconda3\lib\site-packages\pymongo\topology.py", line 205, in _select_servers_loop
    self._error_message(selector))
pymongo.errors.ServerSelectionTimeoutError: localhost:27017: [WinError 10061] 由于目标计算机积极拒绝，无法连接。
2020-03-26 11:40:33 [scrapy] ERROR: Error processing {'author': 'Steve Martin',
 'tags': ['humor', 'obvious', 'simile'],
 'text': '“A day without sunshine is like, you know, night.”'}
Traceback (most recent call last):
  File "c:\users\w\anaconda3\lib\site-packages\twisted\internet\defer.py", line 654, in _runCallbacks
    current.result = callback(current.result, *args, **kw)
  File "c:\users\w\anaconda3\lib\site-packages\scrapy\utils\defer.py", line 154, in f
    return deferred_from_coro(coro_f(*coro_args, **coro_kwargs))
  File "E:\scrapy\ScrapyTutorial-master\tutorial\pipelines.py", line 36, in process_item
    self.db[name].insert(dict(item))
  File "c:\users\w\anaconda3\lib\site-packages\pymongo\collection.py", line 3182, in insert
    check_keys, manipulate, write_concern)
  File "c:\users\w\anaconda3\lib\site-packages\pymongo\collection.py", line 612, in _insert
    bypass_doc_val, session)
  File "c:\users\w\anaconda3\lib\site-packages\pymongo\collection.py", line 600, in _insert_one
    acknowledged, _insert_command, session)
  File "c:\users\w\anaconda3\lib\site-packages\pymongo\mongo_client.py", line 1491, in _retryable_write
    with self._tmp_session(session) as s:
  File "c:\users\w\anaconda3\lib\contextlib.py", line 59, in __enter__
    return next(self.gen)
  File "c:\users\w\anaconda3\lib\site-packages\pymongo\mongo_client.py", line 1820, in _tmp_session
    s = self._ensure_session(session)
  File "c:\users\w\anaconda3\lib\site-packages\pymongo\mongo_client.py", line 1807, in _ensure_session
    return self.__start_session(True, causal_consistency=False)
  File "c:\users\w\anaconda3\lib\site-packages\pymongo\mongo_client.py", line 1760, in __start_session
    server_session = self._get_server_session()
  File "c:\users\w\anaconda3\lib\site-packages\pymongo\mongo_client.py", line 1793, in _get_server_session
    return self._topology.get_server_session()
  File "c:\users\w\anaconda3\lib\site-packages\pymongo\topology.py", line 477, in get_server_session
    None)
  File "c:\users\w\anaconda3\lib\site-packages\pymongo\topology.py", line 205, in _select_servers_loop
    self._error_message(selector))
pymongo.errors.ServerSelectionTimeoutError: localhost:27017: [WinError 10061] 由于目标计算机积极拒绝，无法连接。
2020-03-26 11:40:35 [scrapy] DEBUG: Crawled (200) <GET http://quotes.toscrape.com/page/2/> (referer: http://quotes.toscrape.com/)
2020-03-26 11:41:05 [scrapy] ERROR: Error processing {'author': 'Marilyn Monroe',
 'tags': ['friends', 'heartbreak', 'inspirational', 'life', 'love', 'sisters'],
 'text': '“This life is what you make it. No matter what, yo...'}
Traceback (most recent call last):
  File "c:\users\w\anaconda3\lib\site-packages\twisted\internet\defer.py", line 654, in _runCallbacks
    current.result = callback(current.result, *args, **kw)
  File "c:\users\w\anaconda3\lib\site-packages\scrapy\utils\defer.py", line 154, in f
    return deferred_from_coro(coro_f(*coro_args, **coro_kwargs))
  File "E:\scrapy\ScrapyTutorial-master\tutorial\pipelines.py", line 36, in process_item
    self.db[name].insert(dict(item))
  File "c:\users\w\anaconda3\lib\site-packages\pymongo\collection.py", line 3182, in insert
    check_keys, manipulate, write_concern)
  File "c:\users\w\anaconda3\lib\site-packages\pymongo\collection.py", line 612, in _insert
    bypass_doc_val, session)
  File "c:\users\w\anaconda3\lib\site-packages\pymongo\collection.py", line 600, in _insert_one
    acknowledged, _insert_command, session)
  File "c:\users\w\anaconda3\lib\site-packages\pymongo\mongo_client.py", line 1491, in _retryable_write
    with self._tmp_session(session) as s:
  File "c:\users\w\anaconda3\lib\contextlib.py", line 59, in __enter__
    return next(self.gen)
  File "c:\users\w\anaconda3\lib\site-packages\pymongo\mongo_client.py", line 1820, in _tmp_session
    s = self._ensure_session(session)
  File "c:\users\w\anaconda3\lib\site-packages\pymongo\mongo_client.py", line 1807, in _ensure_session
    return self.__start_session(True, causal_consistency=False)
  File "c:\users\w\anaconda3\lib\site-packages\pymongo\mongo_client.py", line 1760, in __start_session
    server_session = self._get_server_session()
  File "c:\users\w\anaconda3\lib\site-packages\pymongo\mongo_client.py", line 1793, in _get_server_session
    return self._topology.get_server_session()
  File "c:\users\w\anaconda3\lib\site-packages\pymongo\topology.py", line 477, in get_server_session
    None)
  File "c:\users\w\anaconda3\lib\site-packages\pymongo\topology.py", line 205, in _select_servers_loop
    self._error_message(selector))
pymongo.errors.ServerSelectionTimeoutError: localhost:27017: [WinError 10061] 由于目标计算机积极拒绝，无法连接。
2020-03-26 11:41:35 [scrapy] ERROR: Error processing {'author': 'J.K. Rowling',
 'tags': ['courage', 'friends'],
 'text': '“It takes a great deal of bravery to stand up to o...'}
Traceback (most recent call last):
  File "c:\users\w\anaconda3\lib\site-packages\twisted\internet\defer.py", line 654, in _runCallbacks
    current.result = callback(current.result, *args, **kw)
  File "c:\users\w\anaconda3\lib\site-packages\scrapy\utils\defer.py", line 154, in f
    return deferred_from_coro(coro_f(*coro_args, **coro_kwargs))
  File "E:\scrapy\ScrapyTutorial-master\tutorial\pipelines.py", line 36, in process_item
    self.db[name].insert(dict(item))
  File "c:\users\w\anaconda3\lib\site-packages\pymongo\collection.py", line 3182, in insert
    check_keys, manipulate, write_concern)
  File "c:\users\w\anaconda3\lib\site-packages\pymongo\collection.py", line 612, in _insert
    bypass_doc_val, session)
  File "c:\users\w\anaconda3\lib\site-packages\pymongo\collection.py", line 600, in _insert_one
    acknowledged, _insert_command, session)
  File "c:\users\w\anaconda3\lib\site-packages\pymongo\mongo_client.py", line 1491, in _retryable_write
    with self._tmp_session(session) as s:
  File "c:\users\w\anaconda3\lib\contextlib.py", line 59, in __enter__
    return next(self.gen)
  File "c:\users\w\anaconda3\lib\site-packages\pymongo\mongo_client.py", line 1820, in _tmp_session
    s = self._ensure_session(session)
  File "c:\users\w\anaconda3\lib\site-packages\pymongo\mongo_client.py", line 1807, in _ensure_session
    return self.__start_session(True, causal_consistency=False)
  File "c:\users\w\anaconda3\lib\site-packages\pymongo\mongo_client.py", line 1760, in __start_session
    server_session = self._get_server_session()
  File "c:\users\w\anaconda3\lib\site-packages\pymongo\mongo_client.py", line 1793, in _get_server_session
    return self._topology.get_server_session()
  File "c:\users\w\anaconda3\lib\site-packages\pymongo\topology.py", line 477, in get_server_session
    None)
  File "c:\users\w\anaconda3\lib\site-packages\pymongo\topology.py", line 205, in _select_servers_loop
    self._error_message(selector))
pymongo.errors.ServerSelectionTimeoutError: localhost:27017: [WinError 10061] 由于目标计算机积极拒绝，无法连接。
2020-03-26 11:43:36 [scrapy] ERROR: Error processing {'author': 'Albert Einstein',
 'tags': ['simplicity', 'understand'],
 'text': "“If you can't explain it to a six year old, you do..."}
Traceback (most recent call last):
  File "c:\users\w\anaconda3\lib\site-packages\twisted\internet\defer.py", line 654, in _runCallbacks
    current.result = callback(current.result, *args, **kw)
  File "c:\users\w\anaconda3\lib\site-packages\scrapy\utils\defer.py", line 154, in f
    return deferred_from_coro(coro_f(*coro_args, **coro_kwargs))
  File "E:\scrapy\ScrapyTutorial-master\tutorial\pipelines.py", line 36, in process_item
    self.db[name].insert(dict(item))
  File "c:\users\w\anaconda3\lib\site-packages\pymongo\collection.py", line 3182, in insert
    check_keys, manipulate, write_concern)
  File "c:\users\w\anaconda3\lib\site-packages\pymongo\collection.py", line 612, in _insert
    bypass_doc_val, session)
  File "c:\users\w\anaconda3\lib\site-packages\pymongo\collection.py", line 600, in _insert_one
    acknowledged, _insert_command, session)
  File "c:\users\w\anaconda3\lib\site-packages\pymongo\mongo_client.py", line 1491, in _retryable_write
    with self._tmp_session(session) as s:
  File "c:\users\w\anaconda3\lib\contextlib.py", line 59, in __enter__
    return next(self.gen)
  File "c:\users\w\anaconda3\lib\site-packages\pymongo\mongo_client.py", line 1820, in _tmp_session
    s = self._ensure_session(session)
  File "c:\users\w\anaconda3\lib\site-packages\pymongo\mongo_client.py", line 1807, in _ensure_session
    return self.__start_session(True, causal_consistency=False)
  File "c:\users\w\anaconda3\lib\site-packages\pymongo\mongo_client.py", line 1760, in __start_session
    server_session = self._get_server_session()
  File "c:\users\w\anaconda3\lib\site-packages\pymongo\mongo_client.py", line 1793, in _get_server_session
    return self._topology.get_server_session()
  File "c:\users\w\anaconda3\lib\site-packages\pymongo\topology.py", line 477, in get_server_session
    None)
  File "c:\users\w\anaconda3\lib\site-packages\pymongo\topology.py", line 205, in _select_servers_loop
    self._error_message(selector))
pymongo.errors.ServerSelectionTimeoutError: localhost:27017: [WinError 10061] 由于目标计算机积极拒绝，无法连接。
2020-03-26 11:45:37 [scrapy] ERROR: Error processing {'author': 'Bob Marley',
 'tags': ['love'],
 'text': '“You may not be her first, her last, or her only....'}
Traceback (most recent call last):
  File "c:\users\w\anaconda3\lib\site-packages\twisted\internet\defer.py", line 654, in _runCallbacks
    current.result = callback(current.result, *args, **kw)
  File "c:\users\w\anaconda3\lib\site-packages\scrapy\utils\defer.py", line 154, in f
    return deferred_from_coro(coro_f(*coro_args, **coro_kwargs))
  File "E:\scrapy\ScrapyTutorial-master\tutorial\pipelines.py", line 36, in process_item
    self.db[name].insert(dict(item))
  File "c:\users\w\anaconda3\lib\site-packages\pymongo\collection.py", line 3182, in insert
    check_keys, manipulate, write_concern)
  File "c:\users\w\anaconda3\lib\site-packages\pymongo\collection.py", line 612, in _insert
    bypass_doc_val, session)
  File "c:\users\w\anaconda3\lib\site-packages\pymongo\collection.py", line 600, in _insert_one
    acknowledged, _insert_command, session)
  File "c:\users\w\anaconda3\lib\site-packages\pymongo\mongo_client.py", line 1491, in _retryable_write
    with self._tmp_session(session) as s:
  File "c:\users\w\anaconda3\lib\contextlib.py", line 59, in __enter__
    return next(self.gen)
  File "c:\users\w\anaconda3\lib\site-packages\pymongo\mongo_client.py", line 1820, in _tmp_session
    s = self._ensure_session(session)
  File "c:\users\w\anaconda3\lib\site-packages\pymongo\mongo_client.py", line 1807, in _ensure_session
    return self.__start_session(True, causal_consistency=False)
  File "c:\users\w\anaconda3\lib\site-packages\pymongo\mongo_client.py", line 1760, in __start_session
    server_session = self._get_server_session()
  File "c:\users\w\anaconda3\lib\site-packages\pymongo\mongo_client.py", line 1793, in _get_server_session
    return self._topology.get_server_session()
  File "c:\users\w\anaconda3\lib\site-packages\pymongo\topology.py", line 477, in get_server_session
    None)
  File "c:\users\w\anaconda3\lib\site-packages\pymongo\topology.py", line 205, in _select_servers_loop
    self._error_message(selector))
pymongo.errors.ServerSelectionTimeoutError: localhost:27017: [WinError 10061] 由于目标计算机积极拒绝，无法连接。
2020-03-26 11:47:38 [scrapy] ERROR: Error processing {'author': 'Dr. Seuss',
 'tags': ['fantasy'],
 'text': '“I like nonsense, it wakes up the brain cells. Fan...'}
Traceback (most recent call last):
  File "c:\users\w\anaconda3\lib\site-packages\twisted\internet\defer.py", line 654, in _runCallbacks
    current.result = callback(current.result, *args, **kw)
  File "c:\users\w\anaconda3\lib\site-packages\scrapy\utils\defer.py", line 154, in f
    return deferred_from_coro(coro_f(*coro_args, **coro_kwargs))
  File "E:\scrapy\ScrapyTutorial-master\tutorial\pipelines.py", line 36, in process_item
    self.db[name].insert(dict(item))
  File "c:\users\w\anaconda3\lib\site-packages\pymongo\collection.py", line 3182, in insert
    check_keys, manipulate, write_concern)
  File "c:\users\w\anaconda3\lib\site-packages\pymongo\collection.py", line 612, in _insert
    bypass_doc_val, session)
  File "c:\users\w\anaconda3\lib\site-packages\pymongo\collection.py", line 600, in _insert_one
    acknowledged, _insert_command, session)
  File "c:\users\w\anaconda3\lib\site-packages\pymongo\mongo_client.py", line 1491, in _retryable_write
    with self._tmp_session(session) as s:
  File "c:\users\w\anaconda3\lib\contextlib.py", line 59, in __enter__
    return next(self.gen)
  File "c:\users\w\anaconda3\lib\site-packages\pymongo\mongo_client.py", line 1820, in _tmp_session
    s = self._ensure_session(session)
  File "c:\users\w\anaconda3\lib\site-packages\pymongo\mongo_client.py", line 1807, in _ensure_session
    return self.__start_session(True, causal_consistency=False)
  File "c:\users\w\anaconda3\lib\site-packages\pymongo\mongo_client.py", line 1760, in __start_session
    server_session = self._get_server_session()
  File "c:\users\w\anaconda3\lib\site-packages\pymongo\mongo_client.py", line 1793, in _get_server_session
    return self._topology.get_server_session()
  File "c:\users\w\anaconda3\lib\site-packages\pymongo\topology.py", line 477, in get_server_session
    None)
  File "c:\users\w\anaconda3\lib\site-packages\pymongo\topology.py", line 205, in _select_servers_loop
    self._error_message(selector))
pymongo.errors.ServerSelectionTimeoutError: localhost:27017: [WinError 10061] 由于目标计算机积极拒绝，无法连接。
2020-03-26 11:49:38 [scrapy] ERROR: Error processing {'author': 'Douglas Adams',
 'tags': ['life', 'navigation'],
 'text': '“I may not have gone where I intended to go, but I...'}
Traceback (most recent call last):
  File "c:\users\w\anaconda3\lib\site-packages\twisted\internet\defer.py", line 654, in _runCallbacks
    current.result = callback(current.result, *args, **kw)
  File "c:\users\w\anaconda3\lib\site-packages\scrapy\utils\defer.py", line 154, in f
    return deferred_from_coro(coro_f(*coro_args, **coro_kwargs))
  File "E:\scrapy\ScrapyTutorial-master\tutorial\pipelines.py", line 36, in process_item
    self.db[name].insert(dict(item))
  File "c:\users\w\anaconda3\lib\site-packages\pymongo\collection.py", line 3182, in insert
    check_keys, manipulate, write_concern)
  File "c:\users\w\anaconda3\lib\site-packages\pymongo\collection.py", line 612, in _insert
    bypass_doc_val, session)
  File "c:\users\w\anaconda3\lib\site-packages\pymongo\collection.py", line 600, in _insert_one
    acknowledged, _insert_command, session)
  File "c:\users\w\anaconda3\lib\site-packages\pymongo\mongo_client.py", line 1491, in _retryable_write
    with self._tmp_session(session) as s:
  File "c:\users\w\anaconda3\lib\contextlib.py", line 59, in __enter__
    return next(self.gen)
  File "c:\users\w\anaconda3\lib\site-packages\pymongo\mongo_client.py", line 1820, in _tmp_session
    s = self._ensure_session(session)
  File "c:\users\w\anaconda3\lib\site-packages\pymongo\mongo_client.py", line 1807, in _ensure_session
    return self.__start_session(True, causal_consistency=False)
  File "c:\users\w\anaconda3\lib\site-packages\pymongo\mongo_client.py", line 1760, in __start_session
    server_session = self._get_server_session()
  File "c:\users\w\anaconda3\lib\site-packages\pymongo\mongo_client.py", line 1793, in _get_server_session
    return self._topology.get_server_session()
  File "c:\users\w\anaconda3\lib\site-packages\pymongo\topology.py", line 477, in get_server_session
    None)
  File "c:\users\w\anaconda3\lib\site-packages\pymongo\topology.py", line 205, in _select_servers_loop
    self._error_message(selector))
pymongo.errors.ServerSelectionTimeoutError: localhost:27017: [WinError 10061] 由于目标计算机积极拒绝，无法连接。
2020-03-26 11:51:40 [scrapy] ERROR: Error processing {'author': 'Elie Wiesel',
 'tags': ['activism',
          'apathy',
          'hate',
          'indifference',
          'inspirational',
          'love',
          'opposite',
          'philosophy'],
 'text': "“The opposite of love is not hate, it's indifferen..."}
Traceback (most recent call last):
  File "c:\users\w\anaconda3\lib\site-packages\twisted\internet\defer.py", line 654, in _runCallbacks
    current.result = callback(current.result, *args, **kw)
  File "c:\users\w\anaconda3\lib\site-packages\scrapy\utils\defer.py", line 154, in f
    return deferred_from_coro(coro_f(*coro_args, **coro_kwargs))
  File "E:\scrapy\ScrapyTutorial-master\tutorial\pipelines.py", line 36, in process_item
    self.db[name].insert(dict(item))
  File "c:\users\w\anaconda3\lib\site-packages\pymongo\collection.py", line 3182, in insert
    check_keys, manipulate, write_concern)
  File "c:\users\w\anaconda3\lib\site-packages\pymongo\collection.py", line 612, in _insert
    bypass_doc_val, session)
  File "c:\users\w\anaconda3\lib\site-packages\pymongo\collection.py", line 600, in _insert_one
    acknowledged, _insert_command, session)
  File "c:\users\w\anaconda3\lib\site-packages\pymongo\mongo_client.py", line 1491, in _retryable_write
    with self._tmp_session(session) as s:
  File "c:\users\w\anaconda3\lib\contextlib.py", line 59, in __enter__
    return next(self.gen)
  File "c:\users\w\anaconda3\lib\site-packages\pymongo\mongo_client.py", line 1820, in _tmp_session
    s = self._ensure_session(session)
  File "c:\users\w\anaconda3\lib\site-packages\pymongo\mongo_client.py", line 1807, in _ensure_session
    return self.__start_session(True, causal_consistency=False)
  File "c:\users\w\anaconda3\lib\site-packages\pymongo\mongo_client.py", line 1760, in __start_session
    server_session = self._get_server_session()
  File "c:\users\w\anaconda3\lib\site-packages\pymongo\mongo_client.py", line 1793, in _get_server_session
    return self._topology.get_server_session()
  File "c:\users\w\anaconda3\lib\site-packages\pymongo\topology.py", line 477, in get_server_session
    None)
  File "c:\users\w\anaconda3\lib\site-packages\pymongo\topology.py", line 205, in _select_servers_loop
    self._error_message(selector))
pymongo.errors.ServerSelectionTimeoutError: localhost:27017: [WinError 10061] 由于目标计算机积极拒绝，无法连接。
2020-03-26 11:53:41 [scrapy] ERROR: Error processing {'author': 'Friedrich Nietzsche',
 'tags': ['friendship',
          'lack-of-friendship',
          'lack-of-love',
          'love',
          'marriage',
          'unhappy-marriage'],
 'text': '“It is not a lack of love, but a lack of friendshi...'}
Traceback (most recent call last):
  File "c:\users\w\anaconda3\lib\site-packages\twisted\internet\defer.py", line 654, in _runCallbacks
    current.result = callback(current.result, *args, **kw)
  File "c:\users\w\anaconda3\lib\site-packages\scrapy\utils\defer.py", line 154, in f
    return deferred_from_coro(coro_f(*coro_args, **coro_kwargs))
  File "E:\scrapy\ScrapyTutorial-master\tutorial\pipelines.py", line 36, in process_item
    self.db[name].insert(dict(item))
  File "c:\users\w\anaconda3\lib\site-packages\pymongo\collection.py", line 3182, in insert
    check_keys, manipulate, write_concern)
  File "c:\users\w\anaconda3\lib\site-packages\pymongo\collection.py", line 612, in _insert
    bypass_doc_val, session)
  File "c:\users\w\anaconda3\lib\site-packages\pymongo\collection.py", line 600, in _insert_one
    acknowledged, _insert_command, session)
  File "c:\users\w\anaconda3\lib\site-packages\pymongo\mongo_client.py", line 1491, in _retryable_write
    with self._tmp_session(session) as s:
  File "c:\users\w\anaconda3\lib\contextlib.py", line 59, in __enter__
    return next(self.gen)
  File "c:\users\w\anaconda3\lib\site-packages\pymongo\mongo_client.py", line 1820, in _tmp_session
    s = self._ensure_session(session)
  File "c:\users\w\anaconda3\lib\site-packages\pymongo\mongo_client.py", line 1807, in _ensure_session
    return self.__start_session(True, causal_consistency=False)
  File "c:\users\w\anaconda3\lib\site-packages\pymongo\mongo_client.py", line 1760, in __start_session
    server_session = self._get_server_session()
  File "c:\users\w\anaconda3\lib\site-packages\pymongo\mongo_client.py", line 1793, in _get_server_session
    return self._topology.get_server_session()
  File "c:\users\w\anaconda3\lib\site-packages\pymongo\topology.py", line 477, in get_server_session
    None)
  File "c:\users\w\anaconda3\lib\site-packages\pymongo\topology.py", line 205, in _select_servers_loop
    self._error_message(selector))
pymongo.errors.ServerSelectionTimeoutError: localhost:27017: [WinError 10061] 由于目标计算机积极拒绝，无法连接。
2020-03-26 11:55:42 [scrapy] ERROR: Error processing {'author': 'Mark Twain',
 'tags': ['books', 'contentment', 'friends', 'friendship', 'life'],
 'text': '“Good friends, good books, and a sleepy conscience...'}
Traceback (most recent call last):
  File "c:\users\w\anaconda3\lib\site-packages\twisted\internet\defer.py", line 654, in _runCallbacks
    current.result = callback(current.result, *args, **kw)
  File "c:\users\w\anaconda3\lib\site-packages\scrapy\utils\defer.py", line 154, in f
    return deferred_from_coro(coro_f(*coro_args, **coro_kwargs))
  File "E:\scrapy\ScrapyTutorial-master\tutorial\pipelines.py", line 36, in process_item
    self.db[name].insert(dict(item))
  File "c:\users\w\anaconda3\lib\site-packages\pymongo\collection.py", line 3182, in insert
    check_keys, manipulate, write_concern)
  File "c:\users\w\anaconda3\lib\site-packages\pymongo\collection.py", line 612, in _insert
    bypass_doc_val, session)
  File "c:\users\w\anaconda3\lib\site-packages\pymongo\collection.py", line 600, in _insert_one
    acknowledged, _insert_command, session)
  File "c:\users\w\anaconda3\lib\site-packages\pymongo\mongo_client.py", line 1491, in _retryable_write
    with self._tmp_session(session) as s:
  File "c:\users\w\anaconda3\lib\contextlib.py", line 59, in __enter__
    return next(self.gen)
  File "c:\users\w\anaconda3\lib\site-packages\pymongo\mongo_client.py", line 1820, in _tmp_session
    s = self._ensure_session(session)
  File "c:\users\w\anaconda3\lib\site-packages\pymongo\mongo_client.py", line 1807, in _ensure_session
    return self.__start_session(True, causal_consistency=False)
  File "c:\users\w\anaconda3\lib\site-packages\pymongo\mongo_client.py", line 1760, in __start_session
    server_session = self._get_server_session()
  File "c:\users\w\anaconda3\lib\site-packages\pymongo\mongo_client.py", line 1793, in _get_server_session
    return self._topology.get_server_session()
  File "c:\users\w\anaconda3\lib\site-packages\pymongo\topology.py", line 477, in get_server_session
    None)
  File "c:\users\w\anaconda3\lib\site-packages\pymongo\topology.py", line 205, in _select_servers_loop
    self._error_message(selector))
pymongo.errors.ServerSelectionTimeoutError: localhost:27017: [WinError 10061] 由于目标计算机积极拒绝，无法连接。
2020-03-26 12:14:13 [scrapy] ERROR: Error processing {'author': 'Allen Saunders',
 'tags': ['fate', 'life', 'misattributed-john-lennon', 'planning', 'plans'],
 'text': '“Life is what happens to us while we are making ot...'}
Traceback (most recent call last):
  File "c:\users\w\anaconda3\lib\site-packages\twisted\internet\defer.py", line 654, in _runCallbacks
    current.result = callback(current.result, *args, **kw)
  File "c:\users\w\anaconda3\lib\site-packages\scrapy\utils\defer.py", line 154, in f
    return deferred_from_coro(coro_f(*coro_args, **coro_kwargs))
  File "E:\scrapy\ScrapyTutorial-master\tutorial\pipelines.py", line 36, in process_item
    self.db[name].insert(dict(item))
  File "c:\users\w\anaconda3\lib\site-packages\pymongo\collection.py", line 3182, in insert
    check_keys, manipulate, write_concern)
  File "c:\users\w\anaconda3\lib\site-packages\pymongo\collection.py", line 612, in _insert
    bypass_doc_val, session)
  File "c:\users\w\anaconda3\lib\site-packages\pymongo\collection.py", line 600, in _insert_one
    acknowledged, _insert_command, session)
  File "c:\users\w\anaconda3\lib\site-packages\pymongo\mongo_client.py", line 1491, in _retryable_write
    with self._tmp_session(session) as s:
  File "c:\users\w\anaconda3\lib\contextlib.py", line 59, in __enter__
    return next(self.gen)
  File "c:\users\w\anaconda3\lib\site-packages\pymongo\mongo_client.py", line 1820, in _tmp_session
    s = self._ensure_session(session)
  File "c:\users\w\anaconda3\lib\site-packages\pymongo\mongo_client.py", line 1807, in _ensure_session
    return self.__start_session(True, causal_consistency=False)
  File "c:\users\w\anaconda3\lib\site-packages\pymongo\mongo_client.py", line 1760, in __start_session
    server_session = self._get_server_session()
  File "c:\users\w\anaconda3\lib\site-packages\pymongo\mongo_client.py", line 1793, in _get_server_session
    return self._topology.get_server_session()
  File "c:\users\w\anaconda3\lib\site-packages\pymongo\topology.py", line 477, in get_server_session
    None)
  File "c:\users\w\anaconda3\lib\site-packages\pymongo\topology.py", line 205, in _select_servers_loop
    self._error_message(selector))
pymongo.errors.ServerSelectionTimeoutError: localhost:27017: [WinError 10061] 由于目标计算机积极拒绝，无法连接。
2020-03-26 12:15:43 [scrapy] INFO: Closing spider (timeout)
2020-03-26 12:15:43 [scrapy] INFO: Dumping Scrapy stats:
{'downloader/request_bytes': 724,
 'downloader/request_count': 3,
 'downloader/request_method_count/GET': 3,
 'downloader/response_bytes': 6003,
 'downloader/response_count': 3,
 'downloader/response_status_count/200': 2,
 'downloader/response_status_count/404': 1,
 'elapsed_time_seconds': 2748.986798,
 'finish_reason': 'timeout',
 'finish_time': datetime.datetime(2020, 3, 26, 4, 15, 43, 975824),
 'log_count/DEBUG': 13,
 'log_count/ERROR': 57,
 'log_count/INFO': 25,
 'request_depth_max': 2,
 'response_received_count': 3,
 'robotstxt/request_count': 1,
 'robotstxt/response_count': 1,
 'robotstxt/response_status_count/404': 1,
 'scheduler/dequeued': 2,
 'scheduler/dequeued/memory': 2,
 'scheduler/enqueued': 3,
 'scheduler/enqueued/memory': 3,
 'start_time': datetime.datetime(2020, 3, 26, 3, 29, 54, 989026)}
2020-03-26 12:15:43 [scrapy] INFO: Spider closed (timeout)
